Workbook

Sheet Metrica
A1: EMPRESA | B1: TERCERO | C1: N° PRODUCTO | D1: FECHA MAX PARA PAGAR | E1: CUOTA IN | F1: CUOTA FIN | G1: SALDO CAPITAL ANTERIOR | H1: SALDO CAPITAL | I1: CUOTA CAPITAL | J1: INTERES | K1: MORA | L1: TOTAL A PAGAR | M1: DIAS VENCIDO | N1: VALOR PAGADO | O1: FECHA DE PAGO | P1: ESTADO
A2: LAMAR OPTICAL S.A.S | B2: BANCO DE BOGOTÁ | C2: 00656006174 | D2: {=IFERROR(INDEX(DATA!$E$2:$E$1036, MATCH(CONCATENATE(YEAR(TODAY()), MONTH(TODAY()), Metrica!$C2), CONCATENATE(DATA!$A$2:$A$1036, DATA!$D$2:$D$1036), 0)), "")} -> 45559 | E2: {=IFERROR(INDEX(DATA!$F$2:$F$1036, MATCH(CONCATENATE(YEAR(TODAY()), MONTH(TODAY()), Metrica!$C2), CONCATENATE(DATA!$A$2:$A$1036, DATA!$D$2:$D$1036), 0)), "")} -> 35 | F2: {=IFERROR(INDEX(DATA!$G$2:$G$1036, MATCH(CONCATENATE(YEAR(TODAY()), MONTH(TODAY()), Metrica!$C2), CONCATENATE(DATA!$A$2:$A$1036, DATA!$D$2:$D$1036), 0)), "")} -> 0 | G2: {=IFERROR(INDEX(DATA!$Q$2:$Q$1036, MATCH(CONCATENATE(YEAR(TODAY()), MONTH(TODAY()-31), Metrica!$C2), CONCATENATE(DATA!$A$2:$A$1036, DATA!$D$2:$D$1036), 0)), 0)} -> 1944444.6 | H2: {=IFERROR(INDEX(DATA!$Q$2:$Q$1036, MATCH(CONCATENATE(YEAR(TODAY()), MONTH(TODAY()), Metrica!$C2), CONCATENATE(DATA!$A$2:$A$1036, DATA!$D$2:$D$1036), 0)), 0)} -> 0.16000003 | I2: {=IFERROR(INDEX(DATA!$H$2:$H$1036, MATCH(CONCATENATE(YEAR(TODAY()), MONTH(TODAY()), Metrica!$C2), CONCATENATE(DATA!$A$2:$A$1036, DATA!$D$2:$D$1036), 0)), 0)} -> 1944444.4 | J2: {=IFERROR(INDEX(DATA!$I$2:$I$1036, MATCH(CONCATENATE(YEAR(TODAY()), MONTH(TODAY()), Metrica!$C2), CONCATENATE(DATA!$A$2:$A$1036, DATA!$D$2:$D$1036), 0)), 0)} -> 82115.612 | K2: {=IFERROR(INDEX(DATA!$L$2:$L$1036, MATCH(CONCATENATE(YEAR(TODAY()), MONTH(TODAY()), Metrica!$C2), CONCATENATE(DATA!$A$2:$A$1036, DATA!$D$2:$D$1036), 0)), 0)} -> 280638.89 | L2: {=IFERROR(INDEX(DATA!$P$2:$P$1036, MATCH(CONCATENATE(YEAR(TODAY()), MONTH(TODAY()), Metrica!$C2), CONCATENATE(DATA!$A$2:$A$1036, DATA!$D$2:$D$1036), 0)), 0)} -> 2307436.9 | M2: {=IFERROR(INDEX(DATA!$R$2:$R$1036, MATCH(CONCATENATE(YEAR(TODAY()), MONTH(TODAY()), Metrica!$C2), CONCATENATE(DATA!$A$2:$A$1036, DATA!$D$2:$D$1036), 0)), 0)} -> -21 | N2: {=IFERROR(INDEX(DATA!$S$2:$S$1036, MATCH(CONCATENATE(YEAR(TODAY()), MONTH(TODAY()), Metrica!$C2), CONCATENATE(DATA!$A$2:$A$1036, DATA!$D$2:$D$1036), 0)), 0)} -> 0 | O2: {=IFERROR(IF(INDEX(DATA!$O$2:$O$1036,MATCH(CONCATENATE(YEAR(TODAY()), MONTH(TODAY()), Metrica!$C2), CONCATENATE(DATA!$A$2 $A$1036, DATA!$D$2:$D$1036), 0)) = 0,"",INDEX(DATA!$O$2:$O$1036,MATCH(CONCATENATE(YEAR(TODAY()), MONTH(TODAY()), Metrica!$C2), CONCATENATE(DATA!$A$2:$A$1036, DATA!$D$2:$D$1036), 0))),"")} | P2: {=IFERROR(INDEX(DATA!$U$2:$U$1036, MATCH(CONCATENATE(YEAR(TODAY()), MONTH(TODAY()), Metrica!$C2), CONCATENATE(DATA!$A$2:$A$1036, DATA!$D$2:$D$1036), 0)), 0)} -> PENDIENTE
A3: INVERSIONES RUEDA S.A.S | B3: SERFINANZAS | C3: 111000176344 | D3: {=IFERROR(INDEX(DATA!$E$2:$E$1036, MATCH(CONCATENATE(YEAR(TODAY()), MONTH(TODAY()), Metrica!$C3), CONCATENATE(DATA!$A$2:$A$1036, DATA!$D$2:$D$1036), 0)), "")} -> 45561 | E3: {=IFERROR(INDEX(DATA!$F$2:$F$1036, MATCH(CONCATENATE(YEAR(TODAY()), MONTH(TODAY()), Metrica!$C3), CONCATENATE(DATA!$A$2:$A$1036, DATA!$D$2:$D$1036), 0)), "")} -> 28 | F3: {=IFERROR(INDEX(DATA!$G$2:$G$1036, MATCH(CONCATENATE(YEAR(TODAY()), MONTH(TODAY()), Metrica!$C3), CONCATENATE(DATA!$A$2:$A$1036, DATA!$D$2:$D$1036), 0)), "")} -> 8 | G3: {=IFERROR(INDEX(DATA!$Q$2:$Q$1036, MATCH(CONCATENATE(YEAR(TODAY()), MONTH(TODAY()-31), Metrica!$C3), CONCATENATE(DATA!$A$2:$A$1036, DATA!$D$2:$D$1036), 0)), 0)} -> 5134675.5 | H3: {=IFERROR(INDEX(DATA!$Q$2:$Q$1036, MATCH(CONCATENATE(YEAR(TODAY()), MONTH(TODAY()), Metrica!$C3), CONCATENATE(DATA!$A$2:$A$1036, DATA!$D$2:$D$1036), 0)), 0)} -> 4612962.6 | I3: {=IFERROR(INDEX(DATA!$H$2:$H$1036, MATCH(CONCATENATE(YEAR(TODAY()), MONTH(TODAY()), Metrica!$C3), CONCATENATE(DATA!$A$2:$A$1036, DATA!$D$2:$D$1036), 0)), 0)} -> 521712.93 | J3: {=IFERROR(INDEX(DATA!$I$2:$I$1036, MATCH(CONCATENATE(YEAR(TODAY()), MONTH(TODAY()), Metrica!$C3), CONCATENATE(DATA!$A$2:$A$1036, DATA!$D$2:$D$1036), 0)), 0)} -> 84085.088 | K3: {=IFERROR(INDEX(DATA!$L$2:$L$1036, MATCH(CONCATENATE(YEAR(TODAY()), MONTH(TODAY()), Metrica!$C3), CONCATENATE(DATA!$A$2:$A$1036, DATA!$D$2:$D$1036), 0)), 0)} -> 0 | L3: {=IFERROR(INDEX(DATA!$P$2:$P$1036, MATCH(CONCATENATE(YEAR(TODAY()), MONTH(TODAY()), Metrica!$C3), CONCATENATE(DATA!$A$2:$A$1036, DATA!$D$2:$D$1036), 0)), 0)} -> 605798.01 | M3: {=IFERROR(INDEX(DATA!$R$2:$R$1036, MATCH(CONCATENATE(YEAR(TODAY()), MONTH(TODAY()), Metrica!$C3), CONCATENATE(DATA!$A$2:$A$1036, DATA!$D$2:$D$1036), 0)), 0)} -> 8 | N3: {=IFERROR(INDEX(DATA!$S$2:$S$1036, MATCH(CONCATENATE(YEAR(TODAY()), MONTH(TODAY()), Metrica!$C3), CONCATENATE(DATA!$A$2:$A$1036, DATA!$D$2:$D$1036), 0)), 0)} -> 0 | O3: {=IFERROR(IF(INDEX(DATA!$O$2:$O$1036,MATCH(CONCATENATE(YEAR(TODAY()), MONTH(TODAY()), Metrica!$C3), CONCATENATE(DATA!$A$2 $A$1036, DATA!$D$2:$D$1036), 0)) = 0,"",INDEX(DATA!$O$2:$O$1036,MATCH(CONCATENATE(YEAR(TODAY()), MONTH(TODAY()), Metrica!$C3), CONCATENATE(DATA!$A$2:$A$1036, DATA!$D$2:$D$1036), 0))),"")} | P3: {=IFERROR(INDEX(DATA!$U$2:$U$1036, MATCH(CONCATENATE(YEAR(TODAY()), MONTH(TODAY()), Metrica!$C3), CONCATENATE(DATA!$A$2:$A$1036, DATA!$D$2:$D$1036), 0)), 0)} -> PENDIENTE
A4: INVERSIONES RUEDA S.A.S | B4: SERFINANZAS | C4: 111000206579 | D4: {=IFERROR(INDEX(DATA!$E$2:$E$1036, MATCH(CONCATENATE(YEAR(TODAY()), MONTH(TODAY()), Metrica!$C4), CONCATENATE(DATA!$A$2:$A$1036, DATA!$D$2:$D$1036), 0)), "")} -> 45565 | E4: {=IFERROR(INDEX(DATA!$F$2:$F$1036, MATCH(CONCATENATE(YEAR(TODAY()), MONTH(TODAY()), Metrica!$C4), CONCATENATE(DATA!$A$2:$A$1036, DATA!$D$2:$D$1036), 0)), "")} -> 20 | F4: {=IFERROR(INDEX(DATA!$G$2:$G$1036, MATCH(CONCATENATE(YEAR(TODAY()), MONTH(TODAY()), Metrica!$C4), CONCATENATE(DATA!$A$2:$A$1036, DATA!$D$2:$D$1036), 0)), "")} -> 16 | G4: {=IFERROR(INDEX(DATA!$Q$2:$Q$1036, MATCH(CONCATENATE(YEAR(TODAY()), MONTH(TODAY()-31), Metrica!$C4), CONCATENATE(DATA!$A$2:$A$1036, DATA!$D$2:$D$1036), 0)), 0)} -> 5650159.5 | H4: {=IFERROR(INDEX(DATA!$Q$2:$Q$1036, MATCH(CONCATENATE(YEAR(TODAY()), MONTH(TODAY()), Metrica!$C4), CONCATENATE(DATA!$A$2:$A$1036, DATA!$D$2:$D$1036), 0)), 0)} -> 5384474.9 | I4: {=IFERROR(INDEX(DATA!$H$2:$H$1036, MATCH(CONCATENATE(YEAR(TODAY()), MONTH(TODAY()), Metrica!$C4), CONCATENATE(DATA!$A$2:$A$1036, DATA!$D$2:$D$1036), 0)), 0)} -> 265684.6 | J4: {=IFERROR(INDEX(DATA!$I$2:$I$1036, MATCH(CONCATENATE(YEAR(TODAY()), MONTH(TODAY()), Metrica!$C4), CONCATENATE(DATA!$A$2:$A$1036, DATA!$D$2:$D$1036), 0)), 0)} -> 119291.76 | K4: {=IFERROR(INDEX(DATA!$L$2:$L$1036, MATCH(CONCATENATE(YEAR(TODAY()), MONTH(TODAY()), Metrica!$C4), CONCATENATE(DATA!$A$2:$A$1036, DATA!$D$2:$D$1036), 0)), 0)} -> 0 | L4: {=IFERROR(INDEX(DATA!$P$2:$P$1036, MATCH(CONCATENATE(YEAR(TODAY()), MONTH(TODAY()), Metrica!$C4), CONCATENATE(DATA!$A$2:$A$1036, DATA!$D$2:$D$1036), 0)), 0)} -> 384976.37 | M4: {=IFERROR(INDEX(DATA!$R$2:$R$1036, MATCH(CONCATENATE(YEAR(TODAY()), MONTH(TODAY()), Metrica!$C4), CONCATENATE(DATA!$A$2:$A$1036, DATA!$D$2:$D$1036), 0)), 0)} -> 4 | N4: {=IFERROR(INDEX(DATA!$S$2:$S$1036, MATCH(CONCATENATE(YEAR(TODAY()), MONTH(TODAY()), Metrica!$C4), CONCATENATE(DATA!$A$2:$A$1036, DATA!$D$2:$D$1036), 0)), 0)} -> 0 | O4: {=IFERROR(IF(INDEX(DATA!$O$2:$O$1036,MATCH(CONCATENATE(YEAR(TODAY()), MONTH(TODAY()), Metrica!$C4), CONCATENATE(DATA!$A$2 $A$1036, DATA!$D$2:$D$1036), 0)) = 0,"",INDEX(DATA!$O$2:$O$1036,MATCH(CONCATENATE(YEAR(TODAY()), MONTH(TODAY()), Metrica!$C4), CONCATENATE(DATA!$A$2:$A$1036, DATA!$D$2:$D$1036), 0))),"")} | P4: {=IFERROR(INDEX(DATA!$U$2:$U$1036, MATCH(CONCATENATE(YEAR(TODAY()), MONTH(TODAY()), Metrica!$C4), CONCATENATE(DATA!$A$2:$A$1036, DATA!$D$2:$D$1036), 0)), 0)} -> PENDIENTE
A5: INVERSIONES RUEDA S.A.S | B5: SERFINANZAS | C5: 111000194235 | D5: {=IFERROR(INDEX(DATA!$E$2:$E$1036, MATCH(CONCATENATE(YEAR(TODAY()), MONTH(TODAY()), Metrica!$C5), CONCATENATE(DATA!$A$2:$A$1036, DATA!$D$2:$D$1036), 0)), "")} -> 45560 | E5: {=IFERROR(INDEX(DATA!$F$2:$F$1036, MATCH(CONCATENATE(YEAR(TODAY()), MONTH(TODAY()), Metrica!$C5), CONCATENATE(DATA!$A$2:$A$1036, DATA!$D$2:$D$1036), 0)), "")} -> 23 | F5: {=IFERROR(INDEX(DATA!$G$2:$G$1036, MATCH(CONCATENATE(YEAR(TODAY()), MONTH(TODAY()), Metrica!$C5), CONCATENATE(DATA!$A$2:$A$1036, DATA!$D$2:$D$1036), 0)), "")} -> 13 | G5: {=IFERROR(INDEX(DATA!$Q$2:$Q$1036, MATCH(CONCATENATE(YEAR(TODAY()), MONTH(TODAY()-31), Metrica!$C5), CONCATENATE(DATA!$A$2:$A$1036, DATA!$D$2:$D$1036), 0)), 0)} -> 6220317.7 | H5: {=IFERROR(INDEX(DATA!$Q$2:$Q$1036, MATCH(CONCATENATE(YEAR(TODAY()), MONTH(TODAY()), Metrica!$C5), CONCATENATE(DATA!$A$2:$A$1036, DATA!$D$2:$D$1036), 0)), 0)} -> 5825194.1 | I5: {=IFERROR(INDEX(DATA!$H$2:$H$1036, MATCH(CONCATENATE(YEAR(TODAY()), MONTH(TODAY()), Metrica!$C5), CONCATENATE(DATA!$A$2:$A$1036, DATA!$D$2:$D$1036), 0)), 0)} -> 395123.6 | J5: {=IFERROR(INDEX(DATA!$I$2:$I$1036, MATCH(CONCATENATE(YEAR(TODAY()), MONTH(TODAY()), Metrica!$C5), CONCATENATE(DATA!$A$2:$A$1036, DATA!$D$2:$D$1036), 0)), 0)} -> 110824.26 | K5: {=IFERROR(INDEX(DATA!$L$2:$L$1036, MATCH(CONCATENATE(YEAR(TODAY()), MONTH(TODAY()), Metrica!$C5), CONCATENATE(DATA!$A$2:$A$1036, DATA!$D$2:$D$1036), 0)), 0)} -> 0 | L5: {=IFERROR(INDEX(DATA!$P$2:$P$1036, MATCH(CONCATENATE(YEAR(TODAY()), MONTH(TODAY()), Metrica!$C5), CONCATENATE(DATA!$A$2:$A$1036, DATA!$D$2:$D$1036), 0)), 0)} -> 505947.86 | M5: {=IFERROR(INDEX(DATA!$R$2:$R$1036, MATCH(CONCATENATE(YEAR(TODAY()), MONTH(TODAY()), Metrica!$C5), CONCATENATE(DATA!$A$2:$A$1036, DATA!$D$2:$D$1036), 0)), 0)} -> 9 | N5: {=IFERROR(INDEX(DATA!$S$2:$S$1036, MATCH(CONCATENATE(YEAR(TODAY()), MONTH(TODAY()), Metrica!$C5), CONCATENATE(DATA!$A$2:$A$1036, DATA!$D$2:$D$1036), 0)), 0)} -> 0 | O5: {=IFERROR(IF(INDEX(DATA!$O$2:$O$1036,MATCH(CONCATENATE(YEAR(TODAY()), MONTH(TODAY()), Metrica!$C5), CONCATENATE(DATA!$A$2 $A$1036, DATA!$D$2:$D$1036), 0)) = 0,"",INDEX(DATA!$O$2:$O$1036,MATCH(CONCATENATE(YEAR(TODAY()), MONTH(TODAY()), Metrica!$C5), CONCATENATE(DATA!$A$2:$A$1036, DATA!$D$2:$D$1036), 0))),"")} | P5: {=IFERROR(INDEX(DATA!$U$2:$U$1036, MATCH(CONCATENATE(YEAR(TODAY()), MONTH(TODAY()), Metrica!$C5), CONCATENATE(DATA!$A$2:$A$1036, DATA!$D$2:$D$1036), 0)), 0)} -> PENDIENTE
A6: LAMAR OPTICAL S.A.S | B6: BANCOLOMBIA | C6: 8140099320 | D6: {=IFERROR(INDEX(DATA!$E$2:$E$1036, MATCH(CONCATENATE(YEAR(TODAY()), MONTH(TODAY()), Metrica!$C6), CONCATENATE(DATA!$A$2:$A$1036, DATA!$D$2:$D$1036), 0)), "")} -> 45548 | E6: {=IFERROR(INDEX(DATA!$F$2:$F$1036, MATCH(CONCATENATE(YEAR(TODAY()), MONTH(TODAY()), Metrica!$C6), CONCATENATE(DATA!$A$2:$A$1036, DATA!$D$2:$D$1036), 0)), "")} -> 7 | F6: {=IFERROR(INDEX(DATA!$G$2:$G$1036, MATCH(CONCATENATE(YEAR(TODAY()), MONTH(TODAY()), Metrica!$C6), CONCATENATE(DATA!$A$2:$A$1036, DATA!$D$2:$D$1036), 0)), "")} -> 5 | G6: {=IFERROR(INDEX(DATA!$Q$2:$Q$1036, MATCH(CONCATENATE(YEAR(TODAY()), MONTH(TODAY()-31), Metrica!$C6), CONCATENATE(DATA!$A$2:$A$1036, DATA!$D$2:$D$1036), 0)), 0)} -> 8861046 | H6: {=IFERROR(INDEX(DATA!$Q$2:$Q$1036, MATCH(CONCATENATE(YEAR(TODAY()), MONTH(TODAY()), Metrica!$C6), CONCATENATE(DATA!$A$2:$A$1036, DATA!$D$2:$D$1036), 0)), 0)} -> 7384205 | I6: {=IFERROR(INDEX(DATA!$H$2:$H$1036, MATCH(CONCATENATE(YEAR(TODAY()), MONTH(TODAY()), Metrica!$C6), CONCATENATE(DATA!$A$2:$A$1036, DATA!$D$2:$D$1036), 0)), 0)} -> 1476841 | J6: {=IFERROR(INDEX(DATA!$I$2:$I$1036, MATCH(CONCATENATE(YEAR(TODAY()), MONTH(TODAY()), Metrica!$C6), CONCATENATE(DATA!$A$2:$A$1036, DATA!$D$2:$D$1036), 0)), 0)} -> 120510.23 | K6: {=IFERROR(INDEX(DATA!$L$2:$L$1036, MATCH(CONCATENATE(YEAR(TODAY()), MONTH(TODAY()), Metrica!$C6), CONCATENATE(DATA!$A$2:$A$1036, DATA!$D$2:$D$1036), 0)), 0)} -> 8727.564 | L6: {=IFERROR(INDEX(DATA!$P$2:$P$1036, MATCH(CONCATENATE(YEAR(TODAY()), MONTH(TODAY()), Metrica!$C6), CONCATENATE(DATA!$A$2:$A$1036, DATA!$D$2:$D$1036), 0)), 0)} -> 1606078.8 | M6: {=IFERROR(INDEX(DATA!$R$2:$R$1036, MATCH(CONCATENATE(YEAR(TODAY()), MONTH(TODAY()), Metrica!$C6), CONCATENATE(DATA!$A$2:$A$1036, DATA!$D$2:$D$1036), 0)), 0)} -> -10 | N6: {=IFERROR(INDEX(DATA!$S$2:$S$1036, MATCH(CONCATENATE(YEAR(TODAY()), MONTH(TODAY()), Metrica!$C6), CONCATENATE(DATA!$A$2:$A$1036, DATA!$D$2:$D$1036), 0)), 0)} -> 0 | O6: {=IFERROR(IF(INDEX(DATA!$O$2:$O$1036,MATCH(CONCATENATE(YEAR(TODAY()), MONTH(TODAY()), Metrica!$C6), CONCATENATE(DATA!$A$2 $A$1036, DATA!$D$2:$D$1036), 0)) = 0,"",INDEX(DATA!$O$2:$O$1036,MATCH(CONCATENATE(YEAR(TODAY()), MONTH(TODAY()), Metrica!$C6), CONCATENATE(DATA!$A$2:$A$1036, DATA!$D$2:$D$1036), 0))),"")} | P6: {=IFERROR(INDEX(DATA!$U$2:$U$1036, MATCH(CONCATENATE(YEAR(TODAY()), MONTH(TODAY()), Metrica!$C6), CONCATENATE(DATA!$A$2:$A$1036, DATA!$D$2:$D$1036), 0)), 0)} -> PENDIENTE
A7: GLADYS JEANNETH CORREA RUEDA | B7: SERFINANZAS | C7: 5420603691529285 | D7: {=IFERROR(INDEX(DATA!$E$2:$E$1036, MATCH(CONCATENATE(YEAR(TODAY()), MONTH(TODAY()), Metrica!$C7), CONCATENATE(DATA!$A$2:$A$1036, DATA!$D$2:$D$1036), 0)), "")} -> 45540 | E7: {=IFERROR(INDEX(DATA!$F$2:$F$1036, MATCH(CONCATENATE(YEAR(TODAY()), MONTH(TODAY()), Metrica!$C7), CONCATENATE(DATA!$A$2:$A$1036, DATA!$D$2:$D$1036), 0)), "")} -> 21 | F7: {=IFERROR(INDEX(DATA!$G$2:$G$1036, MATCH(CONCATENATE(YEAR(TODAY()), MONTH(TODAY()), Metrica!$C7), CONCATENATE(DATA!$A$2:$A$1036, DATA!$D$2:$D$1036), 0)), "")} -> 27 | G7: {=IFERROR(INDEX(DATA!$Q$2:$Q$1036, MATCH(CONCATENATE(YEAR(TODAY()), MONTH(TODAY()-31), Metrica!$C7), CONCATENATE(DATA!$A$2:$A$1036, DATA!$D$2:$D$1036), 0)), 0)} -> 9537523.9 | H7: {=IFERROR(INDEX(DATA!$Q$2:$Q$1036, MATCH(CONCATENATE(YEAR(TODAY()), MONTH(TODAY()), Metrica!$C7), CONCATENATE(DATA!$A$2:$A$1036, DATA!$D$2:$D$1036), 0)), 0)} -> 9074953.1 | I7: {=IFERROR(INDEX(DATA!$H$2:$H$1036, MATCH(CONCATENATE(YEAR(TODAY()), MONTH(TODAY()), Metrica!$C7), CONCATENATE(DATA!$A$2:$A$1036, DATA!$D$2:$D$1036), 0)), 0)} -> 462570.86 | J7: {=IFERROR(INDEX(DATA!$I$2:$I$1036, MATCH(CONCATENATE(YEAR(TODAY()), MONTH(TODAY()), Metrica!$C7), CONCATENATE(DATA!$A$2:$A$1036, DATA!$D$2:$D$1036), 0)), 0)} -> 68670.172 | K7: {=IFERROR(INDEX(DATA!$L$2:$L$1036, MATCH(CONCATENATE(YEAR(TODAY()), MONTH(TODAY()), Metrica!$C7), CONCATENATE(DATA!$A$2:$A$1036, DATA!$D$2:$D$1036), 0)), 0)} -> 2073122.3 | L7: {=IFERROR(INDEX(DATA!$P$2:$P$1036, MATCH(CONCATENATE(YEAR(TODAY()), MONTH(TODAY()), Metrica!$C7), CONCATENATE(DATA!$A$2:$A$1036, DATA!$D$2:$D$1036), 0)), 0)} -> 2630263.3 | M7: {=IFERROR(INDEX(DATA!$R$2:$R$1036, MATCH(CONCATENATE(YEAR(TODAY()), MONTH(TODAY()), Metrica!$C7), CONCATENATE(DATA!$A$2:$A$1036, DATA!$D$2:$D$1036), 0)), 0)} -> -2 | N7: {=IFERROR(INDEX(DATA!$S$2:$S$1036, MATCH(CONCATENATE(YEAR(TODAY()), MONTH(TODAY()), Metrica!$C7), CONCATENATE(DATA!$A$2:$A$1036, DATA!$D$2:$D$1036), 0)), 0)} -> 0 | O7: {=IFERROR(IF(INDEX(DATA!$O$2:$O$1036,MATCH(CONCATENATE(YEAR(TODAY()), MONTH(TODAY()), Metrica!$C7), CONCATENATE(DATA!$A$2 $A$1036, DATA!$D$2:$D$1036), 0)) = 0,"",INDEX(DATA!$O$2:$O$1036,MATCH(CONCATENATE(YEAR(TODAY()), MONTH(TODAY()), Metrica!$C7), CONCATENATE(DATA!$A$2:$A$1036, DATA!$D$2:$D$1036), 0))),"")} | P7: {=IFERROR(INDEX(DATA!$U$2:$U$1036, MATCH(CONCATENATE(YEAR(TODAY()), MONTH(TODAY()), Metrica!$C7), CONCATENATE(DATA!$A$2:$A$1036, DATA!$D$2:$D$1036), 0)), 0)} -> PENDIENTE
A8: LAMAR OPTICAL S.A.S | B8: BANCOLOMBIA | C8: 8140097009 | D8: {=IFERROR(INDEX(DATA!$E$2:$E$1036, MATCH(CONCATENATE(YEAR(TODAY()), MONTH(TODAY()), Metrica!$C8), CONCATENATE(DATA!$A$2:$A$1036, DATA!$D$2:$D$1036), 0)), "")} -> 45543 | E8: {=IFERROR(INDEX(DATA!$F$2:$F$1036, MATCH(CONCATENATE(YEAR(TODAY()), MONTH(TODAY()), Metrica!$C8), CONCATENATE(DATA!$A$2:$A$1036, DATA!$D$2:$D$1036), 0)), "")} -> 22 | F8: {=IFERROR(INDEX(DATA!$G$2:$G$1036, MATCH(CONCATENATE(YEAR(TODAY()), MONTH(TODAY()), Metrica!$C8), CONCATENATE(DATA!$A$2:$A$1036, DATA!$D$2:$D$1036), 0)), "")} -> 14 | G8: {=IFERROR(INDEX(DATA!$Q$2:$Q$1036, MATCH(CONCATENATE(YEAR(TODAY()), MONTH(TODAY()-31), Metrica!$C8), CONCATENATE(DATA!$A$2:$A$1036, DATA!$D$2:$D$1036), 0)), 0)} -> 9568352 | H8: {=IFERROR(INDEX(DATA!$Q$2:$Q$1036, MATCH(CONCATENATE(YEAR(TODAY()), MONTH(TODAY()), Metrica!$C8), CONCATENATE(DATA!$A$2:$A$1036, DATA!$D$2:$D$1036), 0)), 0)} -> 8930464 | I8: {=IFERROR(INDEX(DATA!$H$2:$H$1036, MATCH(CONCATENATE(YEAR(TODAY()), MONTH(TODAY()), Metrica!$C8), CONCATENATE(DATA!$A$2:$A$1036, DATA!$D$2:$D$1036), 0)), 0)} -> 637888 | J8: {=IFERROR(INDEX(DATA!$I$2:$I$1036, MATCH(CONCATENATE(YEAR(TODAY()), MONTH(TODAY()), Metrica!$C8), CONCATENATE(DATA!$A$2:$A$1036, DATA!$D$2:$D$1036), 0)), 0)} -> 194603.39 | K8: {=IFERROR(INDEX(DATA!$L$2:$L$1036, MATCH(CONCATENATE(YEAR(TODAY()), MONTH(TODAY()), Metrica!$C8), CONCATENATE(DATA!$A$2:$A$1036, DATA!$D$2:$D$1036), 0)), 0)} -> 17579.144 | L8: {=IFERROR(INDEX(DATA!$P$2:$P$1036, MATCH(CONCATENATE(YEAR(TODAY()), MONTH(TODAY()), Metrica!$C8), CONCATENATE(DATA!$A$2:$A$1036, DATA!$D$2:$D$1036), 0)), 0)} -> 850070.53 | M8: {=IFERROR(INDEX(DATA!$R$2:$R$1036, MATCH(CONCATENATE(YEAR(TODAY()), MONTH(TODAY()), Metrica!$C8), CONCATENATE(DATA!$A$2:$A$1036, DATA!$D$2:$D$1036), 0)), 0)} -> -5 | N8: {=IFERROR(INDEX(DATA!$S$2:$S$1036, MATCH(CONCATENATE(YEAR(TODAY()), MONTH(TODAY()), Metrica!$C8), CONCATENATE(DATA!$A$2:$A$1036, DATA!$D$2:$D$1036), 0)), 0)} -> 0 | O8: {=IFERROR(IF(INDEX(DATA!$O$2:$O$1036,MATCH(CONCATENATE(YEAR(TODAY()), MONTH(TODAY()), Metrica!$C8), CONCATENATE(DATA!$A$2 $A$1036, DATA!$D$2:$D$1036), 0)) = 0,"",INDEX(DATA!$O$2:$O$1036,MATCH(CONCATENATE(YEAR(TODAY()), MONTH(TODAY()), Metrica!$C8), CONCATENATE(DATA!$A$2:$A$1036, DATA!$D$2:$D$1036), 0))),"")} | P8: {=IFERROR(INDEX(DATA!$U$2:$U$1036, MATCH(CONCATENATE(YEAR(TODAY()), MONTH(TODAY()), Metrica!$C8), CONCATENATE(DATA!$A$2:$A$1036, DATA!$D$2:$D$1036), 0)), 0)} -> PENDIENTE
A9: LAMAR OPTICAL S.A.S | B9: SERFINANZAS | C9: 111000176362 | D9: {=IFERROR(INDEX(DATA!$E$2:$E$1036, MATCH(CONCATENATE(YEAR(TODAY()), MONTH(TODAY()), Metrica!$C9), CONCATENATE(DATA!$A$2:$A$1036, DATA!$D$2:$D$1036), 0)), "")} -> 45561 | E9: {=IFERROR(INDEX(DATA!$F$2:$F$1036, MATCH(CONCATENATE(YEAR(TODAY()), MONTH(TODAY()), Metrica!$C9), CONCATENATE(DATA!$A$2:$A$1036, DATA!$D$2:$D$1036), 0)), "")} -> 28 | F9: {=IFERROR(INDEX(DATA!$G$2:$G$1036, MATCH(CONCATENATE(YEAR(TODAY()), MONTH(TODAY()), Metrica!$C9), CONCATENATE(DATA!$A$2:$A$1036, DATA!$D$2:$D$1036), 0)), "")} -> 8 | G9: {=IFERROR(INDEX(DATA!$Q$2:$Q$1036, MATCH(CONCATENATE(YEAR(TODAY()), MONTH(TODAY()-31), Metrica!$C9), CONCATENATE(DATA!$A$2:$A$1036, DATA!$D$2:$D$1036), 0)), 0)} -> 9746814 | H9: {=IFERROR(INDEX(DATA!$Q$2:$Q$1036, MATCH(CONCATENATE(YEAR(TODAY()), MONTH(TODAY()), Metrica!$C9), CONCATENATE(DATA!$A$2:$A$1036, DATA!$D$2:$D$1036), 0)), 0)} -> 8702971 | I9: {=IFERROR(INDEX(DATA!$H$2:$H$1036, MATCH(CONCATENATE(YEAR(TODAY()), MONTH(TODAY()), Metrica!$C9), CONCATENATE(DATA!$A$2:$A$1036, DATA!$D$2:$D$1036), 0)), 0)} -> 1043843 | J9: {=IFERROR(INDEX(DATA!$I$2:$I$1036, MATCH(CONCATENATE(YEAR(TODAY()), MONTH(TODAY()), Metrica!$C9), CONCATENATE(DATA!$A$2:$A$1036, DATA!$D$2:$D$1036), 0)), 0)} -> 185580.9 | K9: {=IFERROR(INDEX(DATA!$L$2:$L$1036, MATCH(CONCATENATE(YEAR(TODAY()), MONTH(TODAY()), Metrica!$C9), CONCATENATE(DATA!$A$2:$A$1036, DATA!$D$2:$D$1036), 0)), 0)} -> 0 | L9: {=IFERROR(INDEX(DATA!$P$2:$P$1036, MATCH(CONCATENATE(YEAR(TODAY()), MONTH(TODAY()), Metrica!$C9), CONCATENATE(DATA!$A$2:$A$1036, DATA!$D$2:$D$1036), 0)), 0)} -> 1229424 | M9: {=IFERROR(INDEX(DATA!$R$2:$R$1036, MATCH(CONCATENATE(YEAR(TODAY()), MONTH(TODAY()), Metrica!$C9), CONCATENATE(DATA!$A$2:$A$1036, DATA!$D$2:$D$1036), 0)), 0)} -> 8 | N9: {=IFERROR(INDEX(DATA!$S$2:$S$1036, MATCH(CONCATENATE(YEAR(TODAY()), MONTH(TODAY()), Metrica!$C9), CONCATENATE(DATA!$A$2:$A$1036, DATA!$D$2:$D$1036), 0)), 0)} -> 0 | O9: {=IFERROR(IF(INDEX(DATA!$O$2:$O$1036,MATCH(CONCATENATE(YEAR(TODAY()), MONTH(TODAY()), Metrica!$C9), CONCATENATE(DATA!$A$2 $A$1036, DATA!$D$2:$D$1036), 0)) = 0,"",INDEX(DATA!$O$2:$O$1036,MATCH(CONCATENATE(YEAR(TODAY()), MONTH(TODAY()), Metrica!$C9), CONCATENATE(DATA!$A$2:$A$1036, DATA!$D$2:$D$1036), 0))),"")} | P9: {=IFERROR(INDEX(DATA!$U$2:$U$1036, MATCH(CONCATENATE(YEAR(TODAY()), MONTH(TODAY()), Metrica!$C9), CONCATENATE(DATA!$A$2:$A$1036, DATA!$D$2:$D$1036), 0)), 0)} -> PENDIENTE
A10: INVERSIONES RUEDA S.A.S | B10: SERFINANZAS | C10: 111000149580 | D10: {=IFERROR(INDEX(DATA!$E$2:$E$1036, MATCH(CONCATENATE(YEAR(TODAY()), MONTH(TODAY()), Metrica!$C10), CONCATENATE(DATA!$A$2:$A$1036, DATA!$D$2:$D$1036), 0)), "")} -> 45548 | E10: {=IFERROR(INDEX(DATA!$F$2:$F$1036, MATCH(CONCATENATE(YEAR(TODAY()), MONTH(TODAY()), Metrica!$C10), CONCATENATE(DATA!$A$2:$A$1036, DATA!$D$2:$D$1036), 0)), "")} -> 35 | F10: {=IFERROR(INDEX(DATA!$G$2:$G$1036, MATCH(CONCATENATE(YEAR(TODAY()), MONTH(TODAY()), Metrica!$C10), CONCATENATE(DATA!$A$2:$A$1036, DATA!$D$2:$D$1036), 0)), "")} -> 1 | G10: {=IFERROR(INDEX(DATA!$Q$2:$Q$1036, MATCH(CONCATENATE(YEAR(TODAY()), MONTH(TODAY()-31), Metrica!$C10), CONCATENATE(DATA!$A$2:$A$1036, DATA!$D$2:$D$1036), 0)), 0)} -> 10053092 | H10: {=IFERROR(INDEX(DATA!$Q$2:$Q$1036, MATCH(CONCATENATE(YEAR(TODAY()), MONTH(TODAY()), Metrica!$C10), CONCATENATE(DATA!$A$2:$A$1036, DATA!$D$2:$D$1036), 0)), 0)} -> 6827147.9 | I10: {=IFERROR(INDEX(DATA!$H$2:$H$1036, MATCH(CONCATENATE(YEAR(TODAY()), MONTH(TODAY()), Metrica!$C10), CONCATENATE(DATA!$A$2:$A$1036, DATA!$D$2:$D$1036), 0)), 0)} -> 3225943.9 | J10: {=IFERROR(INDEX(DATA!$I$2:$I$1036, MATCH(CONCATENATE(YEAR(TODAY()), MONTH(TODAY()), Metrica!$C10), CONCATENATE(DATA!$A$2:$A$1036, DATA!$D$2:$D$1036), 0)), 0)} -> 167068.2 | K10: {=IFERROR(INDEX(DATA!$L$2:$L$1036, MATCH(CONCATENATE(YEAR(TODAY()), MONTH(TODAY()), Metrica!$C10), CONCATENATE(DATA!$A$2:$A$1036, DATA!$D$2:$D$1036), 0)), 0)} -> 0 | L10: {=IFERROR(INDEX(DATA!$P$2:$P$1036, MATCH(CONCATENATE(YEAR(TODAY()), MONTH(TODAY()), Metrica!$C10), CONCATENATE(DATA!$A$2:$A$1036, DATA!$D$2:$D$1036), 0)), 0)} -> 3393012.1 | M10: {=IFERROR(INDEX(DATA!$R$2:$R$1036, MATCH(CONCATENATE(YEAR(TODAY()), MONTH(TODAY()), Metrica!$C10), CONCATENATE(DATA!$A$2:$A$1036, DATA!$D$2:$D$1036), 0)), 0)} -> 21 | N10: {=IFERROR(INDEX(DATA!$S$2:$S$1036, MATCH(CONCATENATE(YEAR(TODAY()), MONTH(TODAY()), Metrica!$C10), CONCATENATE(DATA!$A$2:$A$1036, DATA!$D$2:$D$1036), 0)), 0)} -> 0 | O10: {=IFERROR(IF(INDEX(DATA!$O$2:$O$1036,MATCH(CONCATENATE(YEAR(TODAY()), MONTH(TODAY()), Metrica!$C10), CONCATENATE(DATA!$A$2 $A$1036, DATA!$D$2:$D$1036), 0)) = 0,"",INDEX(DATA!$O$2:$O$1036,MATCH(CONCATENATE(YEAR(TODAY()), MONTH(TODAY()), Metrica!$C10), CONCATENATE(DATA!$A$2:$A$1036, DATA!$D$2:$D$1036), 0))),"")} | P10: {=IFERROR(INDEX(DATA!$U$2:$U$1036, MATCH(CONCATENATE(YEAR(TODAY()), MONTH(TODAY()), Metrica!$C10), CONCATENATE(DATA!$A$2:$A$1036, DATA!$D$2:$D$1036), 0)), 0)} -> PENDIENTE
A11: LAMAR OPTICAL S.A.S | B11: SERFINANZAS | C11: 111000206819 | D11: {=IFERROR(INDEX(DATA!$E$2:$E$1036, MATCH(CONCATENATE(YEAR(TODAY()), MONTH(TODAY()), Metrica!$C11), CONCATENATE(DATA!$A$2:$A$1036, DATA!$D$2:$D$1036), 0)), "")} -> 45565 | E11: {=IFERROR(INDEX(DATA!$F$2:$F$1036, MATCH(CONCATENATE(YEAR(TODAY()), MONTH(TODAY()), Metrica!$C11), CONCATENATE(DATA!$A$2:$A$1036, DATA!$D$2:$D$1036), 0)), "")} -> 20 | F11: {=IFERROR(INDEX(DATA!$G$2:$G$1036, MATCH(CONCATENATE(YEAR(TODAY()), MONTH(TODAY()), Metrica!$C11), CONCATENATE(DATA!$A$2:$A$1036, DATA!$D$2:$D$1036), 0)), "")} -> 16 | G11: {=IFERROR(INDEX(DATA!$Q$2:$Q$1036, MATCH(CONCATENATE(YEAR(TODAY()), MONTH(TODAY()-31), Metrica!$C11), CONCATENATE(DATA!$A$2:$A$1036, DATA!$D$2:$D$1036), 0)), 0)} -> 12482227 | H11: {=IFERROR(INDEX(DATA!$Q$2:$Q$1036, MATCH(CONCATENATE(YEAR(TODAY()), MONTH(TODAY()), Metrica!$C11), CONCATENATE(DATA!$A$2:$A$1036, DATA!$D$2:$D$1036), 0)), 0)} -> 11830102 | I11: {=IFERROR(INDEX(DATA!$H$2:$H$1036, MATCH(CONCATENATE(YEAR(TODAY()), MONTH(TODAY()), Metrica!$C11), CONCATENATE(DATA!$A$2:$A$1036, DATA!$D$2:$D$1036), 0)), 0)} -> 652125.61 | J11: {=IFERROR(INDEX(DATA!$I$2:$I$1036, MATCH(CONCATENATE(YEAR(TODAY()), MONTH(TODAY()), Metrica!$C11), CONCATENATE(DATA!$A$2:$A$1036, DATA!$D$2:$D$1036), 0)), 0)} -> 261137.75 | K11: {=IFERROR(INDEX(DATA!$L$2:$L$1036, MATCH(CONCATENATE(YEAR(TODAY()), MONTH(TODAY()), Metrica!$C11), CONCATENATE(DATA!$A$2:$A$1036, DATA!$D$2:$D$1036), 0)), 0)} -> 0 | L11: {=IFERROR(INDEX(DATA!$P$2:$P$1036, MATCH(CONCATENATE(YEAR(TODAY()), MONTH(TODAY()), Metrica!$C11), CONCATENATE(DATA!$A$2:$A$1036, DATA!$D$2:$D$1036), 0)), 0)} -> 913263.35 | M11: {=IFERROR(INDEX(DATA!$R$2:$R$1036, MATCH(CONCATENATE(YEAR(TODAY()), MONTH(TODAY()), Metrica!$C11), CONCATENATE(DATA!$A$2:$A$1036, DATA!$D$2:$D$1036), 0)), 0)} -> 4 | N11: {=IFERROR(INDEX(DATA!$S$2:$S$1036, MATCH(CONCATENATE(YEAR(TODAY()), MONTH(TODAY()), Metrica!$C11), CONCATENATE(DATA!$A$2:$A$1036, DATA!$D$2:$D$1036), 0)), 0)} -> 0 | O11: {=IFERROR(IF(INDEX(DATA!$O$2:$O$1036,MATCH(CONCATENATE(YEAR(TODAY()), MONTH(TODAY()), Metrica!$C11), CONCATENATE(DATA!$A$2 $A$1036, DATA!$D$2:$D$1036), 0)) = 0,"",INDEX(DATA!$O$2:$O$1036,MATCH(CONCATENATE(YEAR(TODAY()), MONTH(TODAY()), Metrica!$C11), CONCATENATE(DATA!$A$2:$A$1036, DATA!$D$2:$D$1036), 0))),"")} | P11: {=IFERROR(INDEX(DATA!$U$2:$U$1036, MATCH(CONCATENATE(YEAR(TODAY()), MONTH(TODAY()), Metrica!$C11), CONCATENATE(DATA!$A$2:$A$1036, DATA!$D$2:$D$1036), 0)), 0)} -> PENDIENTE
A12: LAMAR OPTICAL S.A.S | B12: BANCOLOMBIA | C12: 8140098987 | D12: {=IFERROR(INDEX(DATA!$E$2:$E$1036, MATCH(CONCATENATE(YEAR(TODAY()), MONTH(TODAY()), Metrica!$C12), CONCATENATE(DATA!$A$2:$A$1036, DATA!$D$2:$D$1036), 0)), "")} -> 45564 | E12: {=IFERROR(INDEX(DATA!$F$2:$F$1036, MATCH(CONCATENATE(YEAR(TODAY()), MONTH(TODAY()), Metrica!$C12), CONCATENATE(DATA!$A$2:$A$1036, DATA!$D$2:$D$1036), 0)), "")} -> 10 | F12: {=IFERROR(INDEX(DATA!$G$2:$G$1036, MATCH(CONCATENATE(YEAR(TODAY()), MONTH(TODAY()), Metrica!$C12), CONCATENATE(DATA!$A$2:$A$1036, DATA!$D$2:$D$1036), 0)), "")} -> 2 | G12: {=IFERROR(INDEX(DATA!$Q$2:$Q$1036, MATCH(CONCATENATE(YEAR(TODAY()), MONTH(TODAY()-31), Metrica!$C12), CONCATENATE(DATA!$A$2:$A$1036, DATA!$D$2:$D$1036), 0)), 0)} -> 15000000 | H12: {=IFERROR(INDEX(DATA!$Q$2:$Q$1036, MATCH(CONCATENATE(YEAR(TODAY()), MONTH(TODAY()), Metrica!$C12), CONCATENATE(DATA!$A$2:$A$1036, DATA!$D$2:$D$1036), 0)), 0)} -> 10000000 | I12: {=IFERROR(INDEX(DATA!$H$2:$H$1036, MATCH(CONCATENATE(YEAR(TODAY()), MONTH(TODAY()), Metrica!$C12), CONCATENATE(DATA!$A$2:$A$1036, DATA!$D$2:$D$1036), 0)), 0)} -> 5000000 | J12: {=IFERROR(INDEX(DATA!$I$2:$I$1036, MATCH(CONCATENATE(YEAR(TODAY()), MONTH(TODAY()), Metrica!$C12), CONCATENATE(DATA!$A$2:$A$1036, DATA!$D$2:$D$1036), 0)), 0)} -> 241475 | K12: {=IFERROR(INDEX(DATA!$L$2:$L$1036, MATCH(CONCATENATE(YEAR(TODAY()), MONTH(TODAY()), Metrica!$C12), CONCATENATE(DATA!$A$2:$A$1036, DATA!$D$2:$D$1036), 0)), 0)} -> 204505.67 | L12: {=IFERROR(INDEX(DATA!$P$2:$P$1036, MATCH(CONCATENATE(YEAR(TODAY()), MONTH(TODAY()), Metrica!$C12), CONCATENATE(DATA!$A$2:$A$1036, DATA!$D$2:$D$1036), 0)), 0)} -> 5445980.7 | M12: {=IFERROR(INDEX(DATA!$R$2:$R$1036, MATCH(CONCATENATE(YEAR(TODAY()), MONTH(TODAY()), Metrica!$C12), CONCATENATE(DATA!$A$2:$A$1036, DATA!$D$2:$D$1036), 0)), 0)} -> -26 | N12: {=IFERROR(INDEX(DATA!$S$2:$S$1036, MATCH(CONCATENATE(YEAR(TODAY()), MONTH(TODAY()), Metrica!$C12), CONCATENATE(DATA!$A$2:$A$1036, DATA!$D$2:$D$1036), 0)), 0)} -> 0 | O12: {=IFERROR(IF(INDEX(DATA!$O$2:$O$1036,MATCH(CONCATENATE(YEAR(TODAY()), MONTH(TODAY()), Metrica!$C12), CONCATENATE(DATA!$A$2 $A$1036, DATA!$D$2:$D$1036), 0)) = 0,"",INDEX(DATA!$O$2:$O$1036,MATCH(CONCATENATE(YEAR(TODAY()), MONTH(TODAY()), Metrica!$C12), CONCATENATE(DATA!$A$2:$A$1036, DATA!$D$2:$D$1036), 0))),"")} | P12: {=IFERROR(INDEX(DATA!$U$2:$U$1036, MATCH(CONCATENATE(YEAR(TODAY()), MONTH(TODAY()), Metrica!$C12), CONCATENATE(DATA!$A$2:$A$1036, DATA!$D$2:$D$1036), 0)), 0)} -> PENDIENTE
A13: INVERSIONES RUEDA S.A.S | B13: BANCOLOMBIA | C13: 8140098556 | D13: {=IFERROR(INDEX(DATA!$E$2:$E$1036, MATCH(CONCATENATE(YEAR(TODAY()), MONTH(TODAY()), Metrica!$C13), CONCATENATE(DATA!$A$2:$A$1036, DATA!$D$2:$D$1036), 0)), "")} -> 45565 | E13: {=IFERROR(INDEX(DATA!$F$2:$F$1036, MATCH(CONCATENATE(YEAR(TODAY()), MONTH(TODAY()), Metrica!$C13), CONCATENATE(DATA!$A$2:$A$1036, DATA!$D$2:$D$1036), 0)), "")} -> 13 | F13: {=IFERROR(INDEX(DATA!$G$2:$G$1036, MATCH(CONCATENATE(YEAR(TODAY()), MONTH(TODAY()), Metrica!$C13), CONCATENATE(DATA!$A$2:$A$1036, DATA!$D$2:$D$1036), 0)), "")} -> 9 | G13: {=IFERROR(INDEX(DATA!$Q$2:$Q$1036, MATCH(CONCATENATE(YEAR(TODAY()), MONTH(TODAY()-31), Metrica!$C13), CONCATENATE(DATA!$A$2:$A$1036, DATA!$D$2:$D$1036), 0)), 0)} -> 16859504 | H13: {=IFERROR(INDEX(DATA!$Q$2:$Q$1036, MATCH(CONCATENATE(YEAR(TODAY()), MONTH(TODAY()), Metrica!$C13), CONCATENATE(DATA!$A$2:$A$1036, DATA!$D$2:$D$1036), 0)), 0)} -> 15173582 | I13: {=IFERROR(INDEX(DATA!$H$2:$H$1036, MATCH(CONCATENATE(YEAR(TODAY()), MONTH(TODAY()), Metrica!$C13), CONCATENATE(DATA!$A$2:$A$1036, DATA!$D$2:$D$1036), 0)), 0)} -> 1685922 | J13: {=IFERROR(INDEX(DATA!$I$2:$I$1036, MATCH(CONCATENATE(YEAR(TODAY()), MONTH(TODAY()), Metrica!$C13), CONCATENATE(DATA!$A$2:$A$1036, DATA!$D$2:$D$1036), 0)), 0)} -> 257568.73 | K13: {=IFERROR(INDEX(DATA!$L$2:$L$1036, MATCH(CONCATENATE(YEAR(TODAY()), MONTH(TODAY()), Metrica!$C13), CONCATENATE(DATA!$A$2:$A$1036, DATA!$D$2:$D$1036), 0)), 0)} -> 0 | L13: {=IFERROR(INDEX(DATA!$P$2:$P$1036, MATCH(CONCATENATE(YEAR(TODAY()), MONTH(TODAY()), Metrica!$C13), CONCATENATE(DATA!$A$2:$A$1036, DATA!$D$2:$D$1036), 0)), 0)} -> 1943490.7 | M13: {=IFERROR(INDEX(DATA!$R$2:$R$1036, MATCH(CONCATENATE(YEAR(TODAY()), MONTH(TODAY()), Metrica!$C13), CONCATENATE(DATA!$A$2:$A$1036, DATA!$D$2:$D$1036), 0)), 0)} -> 3 | N13: {=IFERROR(INDEX(DATA!$S$2:$S$1036, MATCH(CONCATENATE(YEAR(TODAY()), MONTH(TODAY()), Metrica!$C13), CONCATENATE(DATA!$A$2:$A$1036, DATA!$D$2:$D$1036), 0)), 0)} -> 0 | O13: {=IFERROR(IF(INDEX(DATA!$O$2:$O$1036,MATCH(CONCATENATE(YEAR(TODAY()), MONTH(TODAY()), Metrica!$C13), CONCATENATE(DATA!$A$2 $A$1036, DATA!$D$2:$D$1036), 0)) = 0,"",INDEX(DATA!$O$2:$O$1036,MATCH(CONCATENATE(YEAR(TODAY()), MONTH(TODAY()), Metrica!$C13), CONCATENATE(DATA!$A$2:$A$1036, DATA!$D$2:$D$1036), 0))),"")} | P13: {=IFERROR(INDEX(DATA!$U$2:$U$1036, MATCH(CONCATENATE(YEAR(TODAY()), MONTH(TODAY()), Metrica!$C13), CONCATENATE(DATA!$A$2:$A$1036, DATA!$D$2:$D$1036), 0)), 0)} -> PENDIENTE
A14: GLADYS JEANNETH CORREA RUEDA | B14: SERFINANZAS | C14: 121000638199 | D14: {=IFERROR(INDEX(DATA!$E$2:$E$1036, MATCH(CONCATENATE(YEAR(TODAY()), MONTH(TODAY()), Metrica!$C14), CONCATENATE(DATA!$A$2:$A$1036, DATA!$D$2:$D$1036), 0)), "")} -> 45545 | E14: {=IFERROR(INDEX(DATA!$F$2:$F$1036, MATCH(CONCATENATE(YEAR(TODAY()), MONTH(TODAY()), Metrica!$C14), CONCATENATE(DATA!$A$2:$A$1036, DATA!$D$2:$D$1036), 0)), "")} -> 30 | F14: {=IFERROR(INDEX(DATA!$G$2:$G$1036, MATCH(CONCATENATE(YEAR(TODAY()), MONTH(TODAY()), Metrica!$C14), CONCATENATE(DATA!$A$2:$A$1036, DATA!$D$2:$D$1036), 0)), "")} -> 30 | G14: {=IFERROR(INDEX(DATA!$Q$2:$Q$1036, MATCH(CONCATENATE(YEAR(TODAY()), MONTH(TODAY()-31), Metrica!$C14), CONCATENATE(DATA!$A$2:$A$1036, DATA!$D$2:$D$1036), 0)), 0)} -> 19644721 | H14: {=IFERROR(INDEX(DATA!$Q$2:$Q$1036, MATCH(CONCATENATE(YEAR(TODAY()), MONTH(TODAY()), Metrica!$C14), CONCATENATE(DATA!$A$2:$A$1036, DATA!$D$2:$D$1036), 0)), 0)} -> 19155132 | I14: {=IFERROR(INDEX(DATA!$H$2:$H$1036, MATCH(CONCATENATE(YEAR(TODAY()), MONTH(TODAY()), Metrica!$C14), CONCATENATE(DATA!$A$2:$A$1036, DATA!$D$2:$D$1036), 0)), 0)} -> 489588.41 | J14: {=IFERROR(INDEX(DATA!$I$2:$I$1036, MATCH(CONCATENATE(YEAR(TODAY()), MONTH(TODAY()), Metrica!$C14), CONCATENATE(DATA!$A$2:$A$1036, DATA!$D$2:$D$1036), 0)), 0)} -> 371285.23 | K14: {=IFERROR(INDEX(DATA!$L$2:$L$1036, MATCH(CONCATENATE(YEAR(TODAY()), MONTH(TODAY()), Metrica!$C14), CONCATENATE(DATA!$A$2:$A$1036, DATA!$D$2:$D$1036), 0)), 0)} -> 0 | L14: {=IFERROR(INDEX(DATA!$P$2:$P$1036, MATCH(CONCATENATE(YEAR(TODAY()), MONTH(TODAY()), Metrica!$C14), CONCATENATE(DATA!$A$2:$A$1036, DATA!$D$2:$D$1036), 0)), 0)} -> 860873.63 | M14: {=IFERROR(INDEX(DATA!$R$2:$R$1036, MATCH(CONCATENATE(YEAR(TODAY()), MONTH(TODAY()), Metrica!$C14), CONCATENATE(DATA!$A$2:$A$1036, DATA!$D$2:$D$1036), 0)), 0)} -> 24 | N14: {=IFERROR(INDEX(DATA!$S$2:$S$1036, MATCH(CONCATENATE(YEAR(TODAY()), MONTH(TODAY()), Metrica!$C14), CONCATENATE(DATA!$A$2:$A$1036, DATA!$D$2:$D$1036), 0)), 0)} -> 0 | O14: {=IFERROR(IF(INDEX(DATA!$O$2:$O$1036,MATCH(CONCATENATE(YEAR(TODAY()), MONTH(TODAY()), Metrica!$C14), CONCATENATE(DATA!$A$2 $A$1036, DATA!$D$2:$D$1036), 0)) = 0,"",INDEX(DATA!$O$2:$O$1036,MATCH(CONCATENATE(YEAR(TODAY()), MONTH(TODAY()), Metrica!$C14), CONCATENATE(DATA!$A$2:$A$1036, DATA!$D$2:$D$1036), 0))),"")} | P14: {=IFERROR(INDEX(DATA!$U$2:$U$1036, MATCH(CONCATENATE(YEAR(TODAY()), MONTH(TODAY()), Metrica!$C14), CONCATENATE(DATA!$A$2:$A$1036, DATA!$D$2:$D$1036), 0)), 0)} -> PENDIENTE
A15: LAMAR OPTICAL S.A.S | B15: SERFINANZAS | C15: 111000149294 | D15: {=IFERROR(INDEX(DATA!$E$2:$E$1036, MATCH(CONCATENATE(YEAR(TODAY()), MONTH(TODAY()), Metrica!$C15), CONCATENATE(DATA!$A$2:$A$1036, DATA!$D$2:$D$1036), 0)), "")} -> 45547 | E15: {=IFERROR(INDEX(DATA!$F$2:$F$1036, MATCH(CONCATENATE(YEAR(TODAY()), MONTH(TODAY()), Metrica!$C15), CONCATENATE(DATA!$A$2:$A$1036, DATA!$D$2:$D$1036), 0)), "")} -> 35 | F15: {=IFERROR(INDEX(DATA!$G$2:$G$1036, MATCH(CONCATENATE(YEAR(TODAY()), MONTH(TODAY()), Metrica!$C15), CONCATENATE(DATA!$A$2:$A$1036, DATA!$D$2:$D$1036), 0)), "")} -> 1 | G15: {=IFERROR(INDEX(DATA!$Q$2:$Q$1036, MATCH(CONCATENATE(YEAR(TODAY()), MONTH(TODAY()-31), Metrica!$C15), CONCATENATE(DATA!$A$2:$A$1036, DATA!$D$2:$D$1036), 0)), 0)} -> 27948785 | H15: {=IFERROR(INDEX(DATA!$Q$2:$Q$1036, MATCH(CONCATENATE(YEAR(TODAY()), MONTH(TODAY()), Metrica!$C15), CONCATENATE(DATA!$A$2:$A$1036, DATA!$D$2:$D$1036), 0)), 0)} -> 22998688 | I15: {=IFERROR(INDEX(DATA!$H$2:$H$1036, MATCH(CONCATENATE(YEAR(TODAY()), MONTH(TODAY()), Metrica!$C15), CONCATENATE(DATA!$A$2:$A$1036, DATA!$D$2:$D$1036), 0)), 0)} -> 4950096.4 | J15: {=IFERROR(INDEX(DATA!$I$2:$I$1036, MATCH(CONCATENATE(YEAR(TODAY()), MONTH(TODAY()), Metrica!$C15), CONCATENATE(DATA!$A$2:$A$1036, DATA!$D$2:$D$1036), 0)), 0)} -> 146692.96 | K15: {=IFERROR(INDEX(DATA!$L$2:$L$1036, MATCH(CONCATENATE(YEAR(TODAY()), MONTH(TODAY()), Metrica!$C15), CONCATENATE(DATA!$A$2:$A$1036, DATA!$D$2:$D$1036), 0)), 0)} -> 0 | L15: {=IFERROR(INDEX(DATA!$P$2:$P$1036, MATCH(CONCATENATE(YEAR(TODAY()), MONTH(TODAY()), Metrica!$C15), CONCATENATE(DATA!$A$2:$A$1036, DATA!$D$2:$D$1036), 0)), 0)} -> 5096789.4 | M15: {=IFERROR(INDEX(DATA!$R$2:$R$1036, MATCH(CONCATENATE(YEAR(TODAY()), MONTH(TODAY()), Metrica!$C15), CONCATENATE(DATA!$A$2:$A$1036, DATA!$D$2:$D$1036), 0)), 0)} -> 22 | N15: {=IFERROR(INDEX(DATA!$S$2:$S$1036, MATCH(CONCATENATE(YEAR(TODAY()), MONTH(TODAY()), Metrica!$C15), CONCATENATE(DATA!$A$2:$A$1036, DATA!$D$2:$D$1036), 0)), 0)} -> 0 | O15: {=IFERROR(IF(INDEX(DATA!$O$2:$O$1036,MATCH(CONCATENATE(YEAR(TODAY()), MONTH(TODAY()), Metrica!$C15), CONCATENATE(DATA!$A$2 $A$1036, DATA!$D$2:$D$1036), 0)) = 0,"",INDEX(DATA!$O$2:$O$1036,MATCH(CONCATENATE(YEAR(TODAY()), MONTH(TODAY()), Metrica!$C15), CONCATENATE(DATA!$A$2:$A$1036, DATA!$D$2:$D$1036), 0))),"")} | P15: {=IFERROR(INDEX(DATA!$U$2:$U$1036, MATCH(CONCATENATE(YEAR(TODAY()), MONTH(TODAY()), Metrica!$C15), CONCATENATE(DATA!$A$2:$A$1036, DATA!$D$2:$D$1036), 0)), 0)} -> PENDIENTE
A16: LAMAR OPTICAL S.A.S | B16: SERFINANZAS | C16: 111000194208 | D16: {=IFERROR(INDEX(DATA!$E$2:$E$1036, MATCH(CONCATENATE(YEAR(TODAY()), MONTH(TODAY()), Metrica!$C16), CONCATENATE(DATA!$A$2:$A$1036, DATA!$D$2:$D$1036), 0)), "")} -> 45560 | E16: {=IFERROR(INDEX(DATA!$F$2:$F$1036, MATCH(CONCATENATE(YEAR(TODAY()), MONTH(TODAY()), Metrica!$C16), CONCATENATE(DATA!$A$2:$A$1036, DATA!$D$2:$D$1036), 0)), "")} -> 23 | F16: {=IFERROR(INDEX(DATA!$G$2:$G$1036, MATCH(CONCATENATE(YEAR(TODAY()), MONTH(TODAY()), Metrica!$C16), CONCATENATE(DATA!$A$2:$A$1036, DATA!$D$2:$D$1036), 0)), "")} -> 13 | G16: {=IFERROR(INDEX(DATA!$Q$2:$Q$1036, MATCH(CONCATENATE(YEAR(TODAY()), MONTH(TODAY()-31), Metrica!$C16), CONCATENATE(DATA!$A$2:$A$1036, DATA!$D$2:$D$1036), 0)), 0)} -> 35960145 | H16: {=IFERROR(INDEX(DATA!$Q$2:$Q$1036, MATCH(CONCATENATE(YEAR(TODAY()), MONTH(TODAY()), Metrica!$C16), CONCATENATE(DATA!$A$2:$A$1036, DATA!$D$2:$D$1036), 0)), 0)} -> 33691408 | I16: {=IFERROR(INDEX(DATA!$H$2:$H$1036, MATCH(CONCATENATE(YEAR(TODAY()), MONTH(TODAY()), Metrica!$C16), CONCATENATE(DATA!$A$2:$A$1036, DATA!$D$2:$D$1036), 0)), 0)} -> 2268737 | J16: {=IFERROR(INDEX(DATA!$I$2:$I$1036, MATCH(CONCATENATE(YEAR(TODAY()), MONTH(TODAY()), Metrica!$C16), CONCATENATE(DATA!$A$2:$A$1036, DATA!$D$2:$D$1036), 0)), 0)} -> 636335.29 | K16: {=IFERROR(INDEX(DATA!$L$2:$L$1036, MATCH(CONCATENATE(YEAR(TODAY()), MONTH(TODAY()), Metrica!$C16), CONCATENATE(DATA!$A$2:$A$1036, DATA!$D$2:$D$1036), 0)), 0)} -> 0 | L16: {=IFERROR(INDEX(DATA!$P$2:$P$1036, MATCH(CONCATENATE(YEAR(TODAY()), MONTH(TODAY()), Metrica!$C16), CONCATENATE(DATA!$A$2:$A$1036, DATA!$D$2:$D$1036), 0)), 0)} -> 2905072.3 | M16: {=IFERROR(INDEX(DATA!$R$2:$R$1036, MATCH(CONCATENATE(YEAR(TODAY()), MONTH(TODAY()), Metrica!$C16), CONCATENATE(DATA!$A$2:$A$1036, DATA!$D$2:$D$1036), 0)), 0)} -> 9 | N16: {=IFERROR(INDEX(DATA!$S$2:$S$1036, MATCH(CONCATENATE(YEAR(TODAY()), MONTH(TODAY()), Metrica!$C16), CONCATENATE(DATA!$A$2:$A$1036, DATA!$D$2:$D$1036), 0)), 0)} -> 0 | O16: {=IFERROR(IF(INDEX(DATA!$O$2:$O$1036,MATCH(CONCATENATE(YEAR(TODAY()), MONTH(TODAY()), Metrica!$C16), CONCATENATE(DATA!$A$2 $A$1036, DATA!$D$2:$D$1036), 0)) = 0,"",INDEX(DATA!$O$2:$O$1036,MATCH(CONCATENATE(YEAR(TODAY()), MONTH(TODAY()), Metrica!$C16), CONCATENATE(DATA!$A$2:$A$1036, DATA!$D$2:$D$1036), 0))),"")} | P16: {=IFERROR(INDEX(DATA!$U$2:$U$1036, MATCH(CONCATENATE(YEAR(TODAY()), MONTH(TODAY()), Metrica!$C16), CONCATENATE(DATA!$A$2:$A$1036, DATA!$D$2:$D$1036), 0)), 0)} -> PENDIENTE
A17: GLADYS JEANNETH CORREA RUEDA | B17: DAVIVIENDA | C17: 5.904046e+15 | D17: {=IFERROR(INDEX(DATA!$E$2:$E$1036, MATCH(CONCATENATE(YEAR(TODAY()), MONTH(TODAY()), Metrica!$C17), CONCATENATE(DATA!$A$2:$A$1036, DATA!$D$2:$D$1036), 0)), "")} -> 45550 | E17: {=IFERROR(INDEX(DATA!$F$2:$F$1036, MATCH(CONCATENATE(YEAR(TODAY()), MONTH(TODAY()), Metrica!$C17), CONCATENATE(DATA!$A$2:$A$1036, DATA!$D$2:$D$1036), 0)), "")} -> 45 | F17: {=IFERROR(INDEX(DATA!$G$2:$G$1036, MATCH(CONCATENATE(YEAR(TODAY()), MONTH(TODAY()), Metrica!$C17), CONCATENATE(DATA!$A$2:$A$1036, DATA!$D$2:$D$1036), 0)), "")} -> 75 | G17: {=IFERROR(INDEX(DATA!$Q$2:$Q$1036, MATCH(CONCATENATE(YEAR(TODAY()), MONTH(TODAY()-31), Metrica!$C17), CONCATENATE(DATA!$A$2:$A$1036, DATA!$D$2:$D$1036), 0)), 0)} -> 47853611 | H17: {=IFERROR(INDEX(DATA!$Q$2:$Q$1036, MATCH(CONCATENATE(YEAR(TODAY()), MONTH(TODAY()), Metrica!$C17), CONCATENATE(DATA!$A$2:$A$1036, DATA!$D$2:$D$1036), 0)), 0)} -> 47253917 | I17: {=IFERROR(INDEX(DATA!$H$2:$H$1036, MATCH(CONCATENATE(YEAR(TODAY()), MONTH(TODAY()), Metrica!$C17), CONCATENATE(DATA!$A$2:$A$1036, DATA!$D$2:$D$1036), 0)), 0)} -> 599694.1 | J17: {=IFERROR(INDEX(DATA!$I$2:$I$1036, MATCH(CONCATENATE(YEAR(TODAY()), MONTH(TODAY()), Metrica!$C17), CONCATENATE(DATA!$A$2:$A$1036, DATA!$D$2:$D$1036), 0)), 0)} -> 371072.86 | K17: {=IFERROR(INDEX(DATA!$L$2:$L$1036, MATCH(CONCATENATE(YEAR(TODAY()), MONTH(TODAY()), Metrica!$C17), CONCATENATE(DATA!$A$2:$A$1036, DATA!$D$2:$D$1036), 0)), 0)} -> 0 | L17: {=IFERROR(INDEX(DATA!$P$2:$P$1036, MATCH(CONCATENATE(YEAR(TODAY()), MONTH(TODAY()), Metrica!$C17), CONCATENATE(DATA!$A$2:$A$1036, DATA!$D$2:$D$1036), 0)), 0)} -> 970766.96 | M17: {=IFERROR(INDEX(DATA!$R$2:$R$1036, MATCH(CONCATENATE(YEAR(TODAY()), MONTH(TODAY()), Metrica!$C17), CONCATENATE(DATA!$A$2:$A$1036, DATA!$D$2:$D$1036), 0)), 0)} -> -12 | N17: {=IFERROR(INDEX(DATA!$S$2:$S$1036, MATCH(CONCATENATE(YEAR(TODAY()), MONTH(TODAY()), Metrica!$C17), CONCATENATE(DATA!$A$2:$A$1036, DATA!$D$2:$D$1036), 0)), 0)} -> 0 | O17: {=IFERROR(IF(INDEX(DATA!$O$2:$O$1036,MATCH(CONCATENATE(YEAR(TODAY()), MONTH(TODAY()), Metrica!$C17), CONCATENATE(DATA!$A$2 $A$1036, DATA!$D$2:$D$1036), 0)) = 0,"",INDEX(DATA!$O$2:$O$1036,MATCH(CONCATENATE(YEAR(TODAY()), MONTH(TODAY()), Metrica!$C17), CONCATENATE(DATA!$A$2:$A$1036, DATA!$D$2:$D$1036), 0))),"")} | P17: {=IFERROR(INDEX(DATA!$U$2:$U$1036, MATCH(CONCATENATE(YEAR(TODAY()), MONTH(TODAY()), Metrica!$C17), CONCATENATE(DATA!$A$2:$A$1036, DATA!$D$2:$D$1036), 0)), 0)} -> PENDIENTE
A18: LAMAR OPTICAL S.A.S | B18: BANCOLOMBIA | C18: 8140099327 | D18: {=IFERROR(INDEX(DATA!$E$2:$E$1036, MATCH(CONCATENATE(YEAR(TODAY()), MONTH(TODAY()), Metrica!$C18), CONCATENATE(DATA!$A$2:$A$1036, DATA!$D$2:$D$1036), 0)), "")} | E18: {=IFERROR(INDEX(DATA!$F$2:$F$1036, MATCH(CONCATENATE(YEAR(TODAY()), MONTH(TODAY()), Metrica!$C18), CONCATENATE(DATA!$A$2:$A$1036, DATA!$D$2:$D$1036), 0)), "")} | F18: {=IFERROR(INDEX(DATA!$G$2:$G$1036, MATCH(CONCATENATE(YEAR(TODAY()), MONTH(TODAY()), Metrica!$C18), CONCATENATE(DATA!$A$2:$A$1036, DATA!$D$2:$D$1036), 0)), "")} | G18: {=IFERROR(INDEX(DATA!$Q$2:$Q$1036, MATCH(CONCATENATE(YEAR(TODAY()), MONTH(TODAY()-31), Metrica!$C18), CONCATENATE(DATA!$A$2:$A$1036, DATA!$D$2:$D$1036), 0)), 0)} -> 63750000 | H18: {=IFERROR(INDEX(DATA!$Q$2:$Q$1036, MATCH(CONCATENATE(YEAR(TODAY()), MONTH(TODAY()), Metrica!$C18), CONCATENATE(DATA!$A$2:$A$1036, DATA!$D$2:$D$1036), 0)), 0)} -> 0 | I18: {=IFERROR(INDEX(DATA!$H$2:$H$1036, MATCH(CONCATENATE(YEAR(TODAY()), MONTH(TODAY()), Metrica!$C18), CONCATENATE(DATA!$A$2:$A$1036, DATA!$D$2:$D$1036), 0)), 0)} -> 0 | J18: {=IFERROR(INDEX(DATA!$I$2:$I$1036, MATCH(CONCATENATE(YEAR(TODAY()), MONTH(TODAY()), Metrica!$C18), CONCATENATE(DATA!$A$2:$A$1036, DATA!$D$2:$D$1036), 0)), 0)} -> 0 | K18: {=IFERROR(INDEX(DATA!$L$2:$L$1036, MATCH(CONCATENATE(YEAR(TODAY()), MONTH(TODAY()), Metrica!$C18), CONCATENATE(DATA!$A$2:$A$1036, DATA!$D$2:$D$1036), 0)), 0)} -> 0 | L18: {=IFERROR(INDEX(DATA!$P$2:$P$1036, MATCH(CONCATENATE(YEAR(TODAY()), MONTH(TODAY()), Metrica!$C18), CONCATENATE(DATA!$A$2:$A$1036, DATA!$D$2:$D$1036), 0)), 0)} -> 0 | M18: {=IFERROR(INDEX(DATA!$R$2:$R$1036, MATCH(CONCATENATE(YEAR(TODAY()), MONTH(TODAY()), Metrica!$C18), CONCATENATE(DATA!$A$2:$A$1036, DATA!$D$2:$D$1036), 0)), 0)} -> 0 | N18: {=IFERROR(INDEX(DATA!$S$2:$S$1036, MATCH(CONCATENATE(YEAR(TODAY()), MONTH(TODAY()), Metrica!$C18), CONCATENATE(DATA!$A$2:$A$1036, DATA!$D$2:$D$1036), 0)), 0)} -> 0 | O18: {=IFERROR(IF(INDEX(DATA!$O$2:$O$1036,MATCH(CONCATENATE(YEAR(TODAY()), MONTH(TODAY()), Metrica!$C18), CONCATENATE(DATA!$A$2 $A$1036, DATA!$D$2:$D$1036), 0)) = 0,"",INDEX(DATA!$O$2:$O$1036,MATCH(CONCATENATE(YEAR(TODAY()), MONTH(TODAY()), Metrica!$C18), CONCATENATE(DATA!$A$2:$A$1036, DATA!$D$2:$D$1036), 0))),"")} | P18: {=IFERROR(INDEX(DATA!$U$2:$U$1036, MATCH(CONCATENATE(YEAR(TODAY()), MONTH(TODAY()), Metrica!$C18), CONCATENATE(DATA!$A$2:$A$1036, DATA!$D$2:$D$1036), 0)), 0)} -> 0
A19: INVERSIONES RUEDA S.A.S | B19: DAVIVIENDA | C19: 7104046002627555 | D19: {=IFERROR(INDEX(DATA!$E$2:$E$1036, MATCH(CONCATENATE(YEAR(TODAY()), MONTH(TODAY()), Metrica!$C19), CONCATENATE(DATA!$A$2:$A$1036, DATA!$D$2:$D$1036), 0)), "")} -> 45565 | E19: {=IFERROR(INDEX(DATA!$F$2:$F$1036, MATCH(CONCATENATE(YEAR(TODAY()), MONTH(TODAY()), Metrica!$C19), CONCATENATE(DATA!$A$2:$A$1036, DATA!$D$2:$D$1036), 0)), "")} -> 13 | F19: {=IFERROR(INDEX(DATA!$G$2:$G$1036, MATCH(CONCATENATE(YEAR(TODAY()), MONTH(TODAY()), Metrica!$C19), CONCATENATE(DATA!$A$2:$A$1036, DATA!$D$2:$D$1036), 0)), "")} -> 23 | G19: {=IFERROR(INDEX(DATA!$Q$2:$Q$1036, MATCH(CONCATENATE(YEAR(TODAY()), MONTH(TODAY()-31), Metrica!$C19), CONCATENATE(DATA!$A$2:$A$1036, DATA!$D$2:$D$1036), 0)), 0)} -> 68666667 | H19: {=IFERROR(INDEX(DATA!$Q$2:$Q$1036, MATCH(CONCATENATE(YEAR(TODAY()), MONTH(TODAY()), Metrica!$C19), CONCATENATE(DATA!$A$2:$A$1036, DATA!$D$2:$D$1036), 0)), 0)} -> 65805556 | I19: {=IFERROR(INDEX(DATA!$H$2:$H$1036, MATCH(CONCATENATE(YEAR(TODAY()), MONTH(TODAY()), Metrica!$C19), CONCATENATE(DATA!$A$2:$A$1036, DATA!$D$2:$D$1036), 0)), 0)} -> 2861111.1 | J19: {=IFERROR(INDEX(DATA!$I$2:$I$1036, MATCH(CONCATENATE(YEAR(TODAY()), MONTH(TODAY()), Metrica!$C19), CONCATENATE(DATA!$A$2:$A$1036, DATA!$D$2:$D$1036), 0)), 0)} -> 1602615.9 | K19: {=IFERROR(INDEX(DATA!$L$2:$L$1036, MATCH(CONCATENATE(YEAR(TODAY()), MONTH(TODAY()), Metrica!$C19), CONCATENATE(DATA!$A$2:$A$1036, DATA!$D$2:$D$1036), 0)), 0)} -> 0 | L19: {=IFERROR(INDEX(DATA!$P$2:$P$1036, MATCH(CONCATENATE(YEAR(TODAY()), MONTH(TODAY()), Metrica!$C19), CONCATENATE(DATA!$A$2:$A$1036, DATA!$D$2:$D$1036), 0)), 0)} -> 4463727 | M19: {=IFERROR(INDEX(DATA!$R$2:$R$1036, MATCH(CONCATENATE(YEAR(TODAY()), MONTH(TODAY()), Metrica!$C19), CONCATENATE(DATA!$A$2:$A$1036, DATA!$D$2:$D$1036), 0)), 0)} -> 4 | N19: {=IFERROR(INDEX(DATA!$S$2:$S$1036, MATCH(CONCATENATE(YEAR(TODAY()), MONTH(TODAY()), Metrica!$C19), CONCATENATE(DATA!$A$2:$A$1036, DATA!$D$2:$D$1036), 0)), 0)} -> 0 | O19: {=IFERROR(IF(INDEX(DATA!$O$2:$O$1036,MATCH(CONCATENATE(YEAR(TODAY()), MONTH(TODAY()), Metrica!$C19), CONCATENATE(DATA!$A$2 $A$1036, DATA!$D$2:$D$1036), 0)) = 0,"",INDEX(DATA!$O$2:$O$1036,MATCH(CONCATENATE(YEAR(TODAY()), MONTH(TODAY()), Metrica!$C19), CONCATENATE(DATA!$A$2:$A$1036, DATA!$D$2:$D$1036), 0))),"")} | P19: {=IFERROR(INDEX(DATA!$U$2:$U$1036, MATCH(CONCATENATE(YEAR(TODAY()), MONTH(TODAY()), Metrica!$C19), CONCATENATE(DATA!$A$2:$A$1036, DATA!$D$2:$D$1036), 0)), 0)} -> PENDIENTE
A20: INVERSIONES RUEDA S.A.S | B20: BANCOLOMBIA | C20: 8140098558 | D20: {=IFERROR(INDEX(DATA!$E$2:$E$1036, MATCH(CONCATENATE(YEAR(TODAY()), MONTH(TODAY()), Metrica!$C20), CONCATENATE(DATA!$A$2:$A$1036, DATA!$D$2:$D$1036), 0)), "")} -> 45565 | E20: {=IFERROR(INDEX(DATA!$F$2:$F$1036, MATCH(CONCATENATE(YEAR(TODAY()), MONTH(TODAY()), Metrica!$C20), CONCATENATE(DATA!$A$2:$A$1036, DATA!$D$2:$D$1036), 0)), "")} -> 13 | F20: {=IFERROR(INDEX(DATA!$G$2:$G$1036, MATCH(CONCATENATE(YEAR(TODAY()), MONTH(TODAY()), Metrica!$C20), CONCATENATE(DATA!$A$2:$A$1036, DATA!$D$2:$D$1036), 0)), "")} -> 35 | G20: {=IFERROR(INDEX(DATA!$Q$2:$Q$1036, MATCH(CONCATENATE(YEAR(TODAY()), MONTH(TODAY()-31), Metrica!$C20), CONCATENATE(DATA!$A$2:$A$1036, DATA!$D$2:$D$1036), 0)), 0)} -> 89292327 | H20: {=IFERROR(INDEX(DATA!$Q$2:$Q$1036, MATCH(CONCATENATE(YEAR(TODAY()), MONTH(TODAY()), Metrica!$C20), CONCATENATE(DATA!$A$2:$A$1036, DATA!$D$2:$D$1036), 0)), 0)} -> 86825325 | I20: {=IFERROR(INDEX(DATA!$H$2:$H$1036, MATCH(CONCATENATE(YEAR(TODAY()), MONTH(TODAY()), Metrica!$C20), CONCATENATE(DATA!$A$2:$A$1036, DATA!$D$2:$D$1036), 0)), 0)} -> 2467002 | J20: {=IFERROR(INDEX(DATA!$I$2:$I$1036, MATCH(CONCATENATE(YEAR(TODAY()), MONTH(TODAY()), Metrica!$C20), CONCATENATE(DATA!$A$2:$A$1036, DATA!$D$2:$D$1036), 0)), 0)} -> 1803311.3 | K20: {=IFERROR(INDEX(DATA!$L$2:$L$1036, MATCH(CONCATENATE(YEAR(TODAY()), MONTH(TODAY()), Metrica!$C20), CONCATENATE(DATA!$A$2:$A$1036, DATA!$D$2:$D$1036), 0)), 0)} -> 0 | L20: {=IFERROR(INDEX(DATA!$P$2:$P$1036, MATCH(CONCATENATE(YEAR(TODAY()), MONTH(TODAY()), Metrica!$C20), CONCATENATE(DATA!$A$2:$A$1036, DATA!$D$2:$D$1036), 0)), 0)} -> 4270313.3 | M20: {=IFERROR(INDEX(DATA!$R$2:$R$1036, MATCH(CONCATENATE(YEAR(TODAY()), MONTH(TODAY()), Metrica!$C20), CONCATENATE(DATA!$A$2:$A$1036, DATA!$D$2:$D$1036), 0)), 0)} -> 3 | N20: {=IFERROR(INDEX(DATA!$S$2:$S$1036, MATCH(CONCATENATE(YEAR(TODAY()), MONTH(TODAY()), Metrica!$C20), CONCATENATE(DATA!$A$2:$A$1036, DATA!$D$2:$D$1036), 0)), 0)} -> 0 | O20: {=IFERROR(IF(INDEX(DATA!$O$2:$O$1036,MATCH(CONCATENATE(YEAR(TODAY()), MONTH(TODAY()), Metrica!$C20), CONCATENATE(DATA!$A$2 $A$1036, DATA!$D$2:$D$1036), 0)) = 0,"",INDEX(DATA!$O$2:$O$1036,MATCH(CONCATENATE(YEAR(TODAY()), MONTH(TODAY()), Metrica!$C20), CONCATENATE(DATA!$A$2:$A$1036, DATA!$D$2:$D$1036), 0))),"")} | P20: {=IFERROR(INDEX(DATA!$U$2:$U$1036, MATCH(CONCATENATE(YEAR(TODAY()), MONTH(TODAY()), Metrica!$C20), CONCATENATE(DATA!$A$2:$A$1036, DATA!$D$2:$D$1036), 0)), 0)} -> PENDIENTE
A21: LAMAR OPTICAL S.A.S | B21: BANCOLDEX | C21: 5000100411250008 | D21: {=IFERROR(INDEX(DATA!$E$2:$E$1036, MATCH(CONCATENATE(YEAR(TODAY()), MONTH(TODAY()), Metrica!$C21), CONCATENATE(DATA!$A$2:$A$1036, DATA!$D$2:$D$1036), 0)), "")} -> 45549 | E21: {=IFERROR(INDEX(DATA!$F$2:$F$1036, MATCH(CONCATENATE(YEAR(TODAY()), MONTH(TODAY()), Metrica!$C21), CONCATENATE(DATA!$A$2:$A$1036, DATA!$D$2:$D$1036), 0)), "")} -> 24 | F21: {=IFERROR(INDEX(DATA!$G$2:$G$1036, MATCH(CONCATENATE(YEAR(TODAY()), MONTH(TODAY()), Metrica!$C21), CONCATENATE(DATA!$A$2:$A$1036, DATA!$D$2:$D$1036), 0)), "")} -> 12 | G21: {=IFERROR(INDEX(DATA!$Q$2:$Q$1036, MATCH(CONCATENATE(YEAR(TODAY()), MONTH(TODAY()-31), Metrica!$C21), CONCATENATE(DATA!$A$2:$A$1036, DATA!$D$2:$D$1036), 0)), 0)} -> 98484840 | H21: {=IFERROR(INDEX(DATA!$Q$2:$Q$1036, MATCH(CONCATENATE(YEAR(TODAY()), MONTH(TODAY()), Metrica!$C21), CONCATENATE(DATA!$A$2:$A$1036, DATA!$D$2:$D$1036), 0)), 0)} -> 90909082 | I21: {=IFERROR(INDEX(DATA!$H$2:$H$1036, MATCH(CONCATENATE(YEAR(TODAY()), MONTH(TODAY()), Metrica!$C21), CONCATENATE(DATA!$A$2:$A$1036, DATA!$D$2:$D$1036), 0)), 0)} -> 7575758 | J21: {=IFERROR(INDEX(DATA!$I$2:$I$1036, MATCH(CONCATENATE(YEAR(TODAY()), MONTH(TODAY()), Metrica!$C21), CONCATENATE(DATA!$A$2:$A$1036, DATA!$D$2:$D$1036), 0)), 0)} -> 1131838.8 | K21: {=IFERROR(INDEX(DATA!$L$2:$L$1036, MATCH(CONCATENATE(YEAR(TODAY()), MONTH(TODAY()), Metrica!$C21), CONCATENATE(DATA!$A$2:$A$1036, DATA!$D$2:$D$1036), 0)), 0)} -> 0 | L21: {=IFERROR(INDEX(DATA!$P$2:$P$1036, MATCH(CONCATENATE(YEAR(TODAY()), MONTH(TODAY()), Metrica!$C21), CONCATENATE(DATA!$A$2:$A$1036, DATA!$D$2:$D$1036), 0)), 0)} -> 8777439.1 | M21: {=IFERROR(INDEX(DATA!$R$2:$R$1036, MATCH(CONCATENATE(YEAR(TODAY()), MONTH(TODAY()), Metrica!$C21), CONCATENATE(DATA!$A$2:$A$1036, DATA!$D$2:$D$1036), 0)), 0)} -> 20 | N21: {=IFERROR(INDEX(DATA!$S$2:$S$1036, MATCH(CONCATENATE(YEAR(TODAY()), MONTH(TODAY()), Metrica!$C21), CONCATENATE(DATA!$A$2:$A$1036, DATA!$D$2:$D$1036), 0)), 0)} -> 0 | O21: {=IFERROR(IF(INDEX(DATA!$O$2:$O$1036,MATCH(CONCATENATE(YEAR(TODAY()), MONTH(TODAY()), Metrica!$C21), CONCATENATE(DATA!$A$2 $A$1036, DATA!$D$2:$D$1036), 0)) = 0,"",INDEX(DATA!$O$2:$O$1036,MATCH(CONCATENATE(YEAR(TODAY()), MONTH(TODAY()), Metrica!$C21), CONCATENATE(DATA!$A$2:$A$1036, DATA!$D$2:$D$1036), 0))),"")} | P21: {=IFERROR(INDEX(DATA!$U$2:$U$1036, MATCH(CONCATENATE(YEAR(TODAY()), MONTH(TODAY()), Metrica!$C21), CONCATENATE(DATA!$A$2:$A$1036, DATA!$D$2:$D$1036), 0)), 0)} -> PENDIENTE
A22: INVERSIONES RUEDA S.A.S | B22: BANCOLOMBIA | C22: 8140098557 | D22: {=IFERROR(INDEX(DATA!$E$2:$E$1036, MATCH(CONCATENATE(YEAR(TODAY()), MONTH(TODAY()), Metrica!$C22), CONCATENATE(DATA!$A$2:$A$1036, DATA!$D$2:$D$1036), 0)), "")} -> 45565 | E22: {=IFERROR(INDEX(DATA!$F$2:$F$1036, MATCH(CONCATENATE(YEAR(TODAY()), MONTH(TODAY()), Metrica!$C22), CONCATENATE(DATA!$A$2:$A$1036, DATA!$D$2:$D$1036), 0)), "")} -> 13 | F22: {=IFERROR(INDEX(DATA!$G$2:$G$1036, MATCH(CONCATENATE(YEAR(TODAY()), MONTH(TODAY()), Metrica!$C22), CONCATENATE(DATA!$A$2:$A$1036, DATA!$D$2:$D$1036), 0)), "")} -> 25 | G22: {=IFERROR(INDEX(DATA!$Q$2:$Q$1036, MATCH(CONCATENATE(YEAR(TODAY()), MONTH(TODAY()-31), Metrica!$C22), CONCATENATE(DATA!$A$2:$A$1036, DATA!$D$2:$D$1036), 0)), 0)} -> 1.0956986e+08 | H22: {=IFERROR(INDEX(DATA!$Q$2:$Q$1036, MATCH(CONCATENATE(YEAR(TODAY()), MONTH(TODAY()), Metrica!$C22), CONCATENATE(DATA!$A$2:$A$1036, DATA!$D$2:$D$1036), 0)), 0)} -> 1.0535564e+08 | I22: {=IFERROR(INDEX(DATA!$H$2:$H$1036, MATCH(CONCATENATE(YEAR(TODAY()), MONTH(TODAY()), Metrica!$C22), CONCATENATE(DATA!$A$2:$A$1036, DATA!$D$2:$D$1036), 0)), 0)} -> 4214225 | J22: {=IFERROR(INDEX(DATA!$I$2:$I$1036, MATCH(CONCATENATE(YEAR(TODAY()), MONTH(TODAY()), Metrica!$C22), CONCATENATE(DATA!$A$2:$A$1036, DATA!$D$2:$D$1036), 0)), 0)} -> 1765262.5 | K22: {=IFERROR(INDEX(DATA!$L$2:$L$1036, MATCH(CONCATENATE(YEAR(TODAY()), MONTH(TODAY()), Metrica!$C22), CONCATENATE(DATA!$A$2:$A$1036, DATA!$D$2:$D$1036), 0)), 0)} -> 0 | L22: {=IFERROR(INDEX(DATA!$P$2:$P$1036, MATCH(CONCATENATE(YEAR(TODAY()), MONTH(TODAY()), Metrica!$C22), CONCATENATE(DATA!$A$2:$A$1036, DATA!$D$2:$D$1036), 0)), 0)} -> 5979487.5 | M22: {=IFERROR(INDEX(DATA!$R$2:$R$1036, MATCH(CONCATENATE(YEAR(TODAY()), MONTH(TODAY()), Metrica!$C22), CONCATENATE(DATA!$A$2:$A$1036, DATA!$D$2:$D$1036), 0)), 0)} -> 3 | N22: {=IFERROR(INDEX(DATA!$S$2:$S$1036, MATCH(CONCATENATE(YEAR(TODAY()), MONTH(TODAY()), Metrica!$C22), CONCATENATE(DATA!$A$2:$A$1036, DATA!$D$2:$D$1036), 0)), 0)} -> 0 | O22: {=IFERROR(IF(INDEX(DATA!$O$2:$O$1036,MATCH(CONCATENATE(YEAR(TODAY()), MONTH(TODAY()), Metrica!$C22), CONCATENATE(DATA!$A$2 $A$1036, DATA!$D$2:$D$1036), 0)) = 0,"",INDEX(DATA!$O$2:$O$1036,MATCH(CONCATENATE(YEAR(TODAY()), MONTH(TODAY()), Metrica!$C22), CONCATENATE(DATA!$A$2:$A$1036, DATA!$D$2:$D$1036), 0))),"")} | P22: {=IFERROR(INDEX(DATA!$U$2:$U$1036, MATCH(CONCATENATE(YEAR(TODAY()), MONTH(TODAY()), Metrica!$C22), CONCATENATE(DATA!$A$2:$A$1036, DATA!$D$2:$D$1036), 0)), 0)} -> PENDIENTE
A23: LAMAR OPTICAL S.A.S | B23: BANCOLOMBIA | C23: 8140098501 | D23: {=IFERROR(INDEX(DATA!$E$2:$E$1036, MATCH(CONCATENATE(YEAR(TODAY()), MONTH(TODAY()), Metrica!$C23), CONCATENATE(DATA!$A$2:$A$1036, DATA!$D$2:$D$1036), 0)), "")} -> 45553 | E23: {=IFERROR(INDEX(DATA!$F$2:$F$1036, MATCH(CONCATENATE(YEAR(TODAY()), MONTH(TODAY()), Metrica!$C23), CONCATENATE(DATA!$A$2:$A$1036, DATA!$D$2:$D$1036), 0)), "")} -> 13 | F23: {=IFERROR(INDEX(DATA!$G$2:$G$1036, MATCH(CONCATENATE(YEAR(TODAY()), MONTH(TODAY()), Metrica!$C23), CONCATENATE(DATA!$A$2:$A$1036, DATA!$D$2:$D$1036), 0)), "")} -> 39 | G23: {=IFERROR(INDEX(DATA!$Q$2:$Q$1036, MATCH(CONCATENATE(YEAR(TODAY()), MONTH(TODAY()-31), Metrica!$C23), CONCATENATE(DATA!$A$2:$A$1036, DATA!$D$2:$D$1036), 0)), 0)} -> 1.478212e+08 | H23: {=IFERROR(INDEX(DATA!$Q$2:$Q$1036, MATCH(CONCATENATE(YEAR(TODAY()), MONTH(TODAY()), Metrica!$C23), CONCATENATE(DATA!$A$2:$A$1036, DATA!$D$2:$D$1036), 0)), 0)} -> 1.4412567e+08 | I23: {=IFERROR(INDEX(DATA!$H$2:$H$1036, MATCH(CONCATENATE(YEAR(TODAY()), MONTH(TODAY()), Metrica!$C23), CONCATENATE(DATA!$A$2:$A$1036, DATA!$D$2:$D$1036), 0)), 0)} -> 3695530.1 | J23: {=IFERROR(INDEX(DATA!$I$2:$I$1036, MATCH(CONCATENATE(YEAR(TODAY()), MONTH(TODAY()), Metrica!$C23), CONCATENATE(DATA!$A$2:$A$1036, DATA!$D$2:$D$1036), 0)), 0)} -> 2715996.5 | K23: {=IFERROR(INDEX(DATA!$L$2:$L$1036, MATCH(CONCATENATE(YEAR(TODAY()), MONTH(TODAY()), Metrica!$C23), CONCATENATE(DATA!$A$2:$A$1036, DATA!$D$2:$D$1036), 0)), 0)} -> 1350887.7 | L23: {=IFERROR(INDEX(DATA!$P$2:$P$1036, MATCH(CONCATENATE(YEAR(TODAY()), MONTH(TODAY()), Metrica!$C23), CONCATENATE(DATA!$A$2:$A$1036, DATA!$D$2:$D$1036), 0)), 0)} -> 7762414.3 | M23: {=IFERROR(INDEX(DATA!$R$2:$R$1036, MATCH(CONCATENATE(YEAR(TODAY()), MONTH(TODAY()), Metrica!$C23), CONCATENATE(DATA!$A$2:$A$1036, DATA!$D$2:$D$1036), 0)), 0)} -> -15 | N23: {=IFERROR(INDEX(DATA!$S$2:$S$1036, MATCH(CONCATENATE(YEAR(TODAY()), MONTH(TODAY()), Metrica!$C23), CONCATENATE(DATA!$A$2:$A$1036, DATA!$D$2:$D$1036), 0)), 0)} -> 0 | O23: {=IFERROR(IF(INDEX(DATA!$O$2:$O$1036,MATCH(CONCATENATE(YEAR(TODAY()), MONTH(TODAY()), Metrica!$C23), CONCATENATE(DATA!$A$2 $A$1036, DATA!$D$2:$D$1036), 0)) = 0,"",INDEX(DATA!$O$2:$O$1036,MATCH(CONCATENATE(YEAR(TODAY()), MONTH(TODAY()), Metrica!$C23), CONCATENATE(DATA!$A$2:$A$1036, DATA!$D$2:$D$1036), 0))),"")} | P23: {=IFERROR(INDEX(DATA!$U$2:$U$1036, MATCH(CONCATENATE(YEAR(TODAY()), MONTH(TODAY()), Metrica!$C23), CONCATENATE(DATA!$A$2:$A$1036, DATA!$D$2:$D$1036), 0)), 0)} -> PENDIENTE
A24: LAMAR OPTICAL S.A.S | B24: DAVIVIENDA | C24: 7104046002628157 | D24: {=IFERROR(INDEX(DATA!$E$2:$E$1036, MATCH(CONCATENATE(YEAR(TODAY()), MONTH(TODAY()), Metrica!$C24), CONCATENATE(DATA!$A$2:$A$1036, DATA!$D$2:$D$1036), 0)), "")} -> 45537 | E24: {=IFERROR(INDEX(DATA!$F$2:$F$1036, MATCH(CONCATENATE(YEAR(TODAY()), MONTH(TODAY()), Metrica!$C24), CONCATENATE(DATA!$A$2:$A$1036, DATA!$D$2:$D$1036), 0)), "")} -> 12 | F24: {=IFERROR(INDEX(DATA!$G$2:$G$1036, MATCH(CONCATENATE(YEAR(TODAY()), MONTH(TODAY()), Metrica!$C24), CONCATENATE(DATA!$A$2:$A$1036, DATA!$D$2:$D$1036), 0)), "")} -> 24 | G24: {=IFERROR(INDEX(DATA!$Q$2:$Q$1036, MATCH(CONCATENATE(YEAR(TODAY()), MONTH(TODAY()-31), Metrica!$C24), CONCATENATE(DATA!$A$2:$A$1036, DATA!$D$2:$D$1036), 0)), 0)} -> 168750000 | H24: {=IFERROR(INDEX(DATA!$Q$2:$Q$1036, MATCH(CONCATENATE(YEAR(TODAY()), MONTH(TODAY()), Metrica!$C24), CONCATENATE(DATA!$A$2:$A$1036, DATA!$D$2:$D$1036), 0)), 0)} -> 162000000 | I24: {=IFERROR(INDEX(DATA!$H$2:$H$1036, MATCH(CONCATENATE(YEAR(TODAY()), MONTH(TODAY()), Metrica!$C24), CONCATENATE(DATA!$A$2:$A$1036, DATA!$D$2:$D$1036), 0)), 0)} -> 6750000 | J24: {=IFERROR(INDEX(DATA!$I$2:$I$1036, MATCH(CONCATENATE(YEAR(TODAY()), MONTH(TODAY()), Metrica!$C24), CONCATENATE(DATA!$A$2:$A$1036, DATA!$D$2:$D$1036), 0)), 0)} -> 2937087 | K24: {=IFERROR(INDEX(DATA!$L$2:$L$1036, MATCH(CONCATENATE(YEAR(TODAY()), MONTH(TODAY()), Metrica!$C24), CONCATENATE(DATA!$A$2:$A$1036, DATA!$D$2:$D$1036), 0)), 0)} -> 1697040.6 | L24: {=IFERROR(INDEX(DATA!$P$2:$P$1036, MATCH(CONCATENATE(YEAR(TODAY()), MONTH(TODAY()), Metrica!$C24), CONCATENATE(DATA!$A$2:$A$1036, DATA!$D$2:$D$1036), 0)), 0)} -> 17552981 | M24: {=IFERROR(INDEX(DATA!$R$2:$R$1036, MATCH(CONCATENATE(YEAR(TODAY()), MONTH(TODAY()), Metrica!$C24), CONCATENATE(DATA!$A$2:$A$1036, DATA!$D$2:$D$1036), 0)), 0)} -> 1 | N24: {=IFERROR(INDEX(DATA!$S$2:$S$1036, MATCH(CONCATENATE(YEAR(TODAY()), MONTH(TODAY()), Metrica!$C24), CONCATENATE(DATA!$A$2:$A$1036, DATA!$D$2:$D$1036), 0)), 0)} -> 2862725 | O24: {=IFERROR(IF(INDEX(DATA!$O$2:$O$1036,MATCH(CONCATENATE(YEAR(TODAY()), MONTH(TODAY()), Metrica!$C24), CONCATENATE(DATA!$A$2 $A$1036, DATA!$D$2:$D$1036), 0)) = 0,"",INDEX(DATA!$O$2:$O$1036,MATCH(CONCATENATE(YEAR(TODAY()), MONTH(TODAY()), Metrica!$C24), CONCATENATE(DATA!$A$2:$A$1036, DATA!$D$2:$D$1036), 0))),"")} | P24: {=IFERROR(INDEX(DATA!$U$2:$U$1036, MATCH(CONCATENATE(YEAR(TODAY()), MONTH(TODAY()), Metrica!$C24), CONCATENATE(DATA!$A$2:$A$1036, DATA!$D$2:$D$1036), 0)), 0)} -> ABONADO
A25: LAMAR OPTICAL S.A.S | B25: BANCOLOMBIA | C25: 8140098503 | D25: {=IFERROR(INDEX(DATA!$E$2:$E$1036, MATCH(CONCATENATE(YEAR(TODAY()), MONTH(TODAY()), Metrica!$C25), CONCATENATE(DATA!$A$2:$A$1036, DATA!$D$2:$D$1036), 0)), "")} -> 45553 | E25: {=IFERROR(INDEX(DATA!$F$2:$F$1036, MATCH(CONCATENATE(YEAR(TODAY()), MONTH(TODAY()), Metrica!$C25), CONCATENATE(DATA!$A$2:$A$1036, DATA!$D$2:$D$1036), 0)), "")} -> 13 | F25: {=IFERROR(INDEX(DATA!$G$2:$G$1036, MATCH(CONCATENATE(YEAR(TODAY()), MONTH(TODAY()), Metrica!$C25), CONCATENATE(DATA!$A$2:$A$1036, DATA!$D$2:$D$1036), 0)), "")} -> 46 | G25: {=IFERROR(INDEX(DATA!$Q$2:$Q$1036, MATCH(CONCATENATE(YEAR(TODAY()), MONTH(TODAY()-31), Metrica!$C25), CONCATENATE(DATA!$A$2:$A$1036, DATA!$D$2:$D$1036), 0)), 0)} -> 1.7761673e+08 | H25: {=IFERROR(INDEX(DATA!$Q$2:$Q$1036, MATCH(CONCATENATE(YEAR(TODAY()), MONTH(TODAY()), Metrica!$C25), CONCATENATE(DATA!$A$2:$A$1036, DATA!$D$2:$D$1036), 0)), 0)} -> 1.7383765e+08 | I25: {=IFERROR(INDEX(DATA!$H$2:$H$1036, MATCH(CONCATENATE(YEAR(TODAY()), MONTH(TODAY()), Metrica!$C25), CONCATENATE(DATA!$A$2:$A$1036, DATA!$D$2:$D$1036), 0)), 0)} -> 3779079.4 | J25: {=IFERROR(INDEX(DATA!$I$2:$I$1036, MATCH(CONCATENATE(YEAR(TODAY()), MONTH(TODAY()), Metrica!$C25), CONCATENATE(DATA!$A$2:$A$1036, DATA!$D$2:$D$1036), 0)), 0)} -> 2957550.4 | K25: {=IFERROR(INDEX(DATA!$L$2:$L$1036, MATCH(CONCATENATE(YEAR(TODAY()), MONTH(TODAY()), Metrica!$C25), CONCATENATE(DATA!$A$2:$A$1036, DATA!$D$2:$D$1036), 0)), 0)} -> 3492805.2 | L25: {=IFERROR(INDEX(DATA!$P$2:$P$1036, MATCH(CONCATENATE(YEAR(TODAY()), MONTH(TODAY()), Metrica!$C25), CONCATENATE(DATA!$A$2:$A$1036, DATA!$D$2:$D$1036), 0)), 0)} -> 10229435 | M25: {=IFERROR(INDEX(DATA!$R$2:$R$1036, MATCH(CONCATENATE(YEAR(TODAY()), MONTH(TODAY()), Metrica!$C25), CONCATENATE(DATA!$A$2:$A$1036, DATA!$D$2:$D$1036), 0)), 0)} -> -15 | N25: {=IFERROR(INDEX(DATA!$S$2:$S$1036, MATCH(CONCATENATE(YEAR(TODAY()), MONTH(TODAY()), Metrica!$C25), CONCATENATE(DATA!$A$2:$A$1036, DATA!$D$2:$D$1036), 0)), 0)} -> 0 | O25: {=IFERROR(IF(INDEX(DATA!$O$2:$O$1036,MATCH(CONCATENATE(YEAR(TODAY()), MONTH(TODAY()), Metrica!$C25), CONCATENATE(DATA!$A$2 $A$1036, DATA!$D$2:$D$1036), 0)) = 0,"",INDEX(DATA!$O$2:$O$1036,MATCH(CONCATENATE(YEAR(TODAY()), MONTH(TODAY()), Metrica!$C25), CONCATENATE(DATA!$A$2:$A$1036, DATA!$D$2:$D$1036), 0))),"")} | P25: {=IFERROR(INDEX(DATA!$U$2:$U$1036, MATCH(CONCATENATE(YEAR(TODAY()), MONTH(TODAY()), Metrica!$C25), CONCATENATE(DATA!$A$2:$A$1036, DATA!$D$2:$D$1036), 0)), 0)} -> PENDIENTE
